Workbook
Name Categorias: controle!#REF!

Sheet Pesquisa Global
A1: PESQUISA DE EQUIPAMENTOS | X1: Tipos | Y1: Marcas | Z1: Departamentos | AA1: Status | AB1: Modos
X2: Todos | Y2: Todas | Z2: Todos | AA2: Todos | AB2: Contém
X3: Adaptador de rede | Y3: Apple | Z3: Administração | AA3: BOM | AB3: Começa com
A4: PESQUISAR | X4: Celular | Y4: BROTHER | Z4: Administrativo | AA4: Não informado | AB4: Exata
X5: Componente | Y5: C3 Tech (Distribuído por Coletek) | Z5: Almoxarifado | AA5: OK
A6: TIPO DE EQUIPAMENTO | D6: MARCA | G6: DEPARTAMENTO | J6: STATUS | M6: CORRESPONDÊNCIA | X6: Desktop | Y6: CISCO | Z6: Áudio | AA6: RUIM
A7: Todos | D7: Todas | G7: Todos | J7: Todos | M7: Contém | X7: Equipamento de rede | Y7: Dell | Z7: AUDIO HIBRIDA
X8: Fonte/Conector | Y8: DELL | Z8: Cabine OFF
A9: EQUIPAMENTOS ENCONTRADOS | D9: DESKTOPS / MICROS | G9: MONITORES | J9: OUTROS EQUIPAMENTOS | M9: RESPONSÁVEIS | X9: Impressora | Y9: EPSON | Z9: Camarim
A10: {=_xlfn.LET(_xlpm.q,TRIM($B$4),_xlpm.tp,$A$7,_xlpm.mk,$D$7,_xlpm.dp,$G$7,_xlpm.st,$J$7,_xlpm.md,$M$7,_xlpm.b,'Índice Equipamentos'!$A$2:$T$563,_xlpm.txt,INDEX(_xlpm.b,,20)&"",_xlpm.oq,IF(_xlpm.q="",1,_xlfn.SWITCH(_xlpm.md,"Exata",LOWER(_xlpm.txt)=LOWER(_xlpm.q),"Começa com",LEFT(LOWER(_xlpm.txt),LEN(_xlpm.q))=LOWER(_xlpm.q),ISNUMBER(SEARCH(_xlpm.q,_xlpm.txt)))),_xlpm.ot,IF(_xlpm.tp="Todos",1,--(INDEX(_xlpm.b,,1)=_xlpm.tp)),_xlpm.om,IF(_xlpm.mk="Todas",1,--(INDEX(_xlpm.b,,7)=_xlpm.mk)),_xlpm.od,IF(_xlpm.dp="Todos",1,--(INDEX(_xlpm.b,,4)=_xlpm.dp)),_xlpm.os,IF(_xlpm.st="Todos",1,--(INDEX(_xlpm.b,,10)=_xlpm.st)),_xlpm.ok,_xlpm.oq*_xlpm.ot*_xlpm.om*_xlpm.od*_xlpm.os,SUM(--_xlpm.ok))} -> 1 | D10: {=_xlfn.LET(_xlpm.q,TRIM($B$4),_xlpm.tp,$A$7,_xlpm.mk,$D$7,_xlpm.dp,$G$7,_xlpm.st,$J$7,_xlpm.md,$M$7,_xlpm.b,'Índice Equipamentos'!$A$2:$T$563,_xlpm.txt,INDEX(_xlpm.b,,20)&"",_xlpm.oq,IF(_xlpm.q="",1,_xlfn.SWITCH(_xlpm.md,"Exata",LOWER(_xlpm.txt)=LOWER(_xlpm.q),"Começa com",LEFT(LOWER(_xlpm.txt),LEN(_xlpm.q))=LOWER(_xlpm.q),ISNUMBER(SEARCH(_xlpm.q,_xlpm.txt)))),_xlpm.ot,IF(_xlpm.tp="Todos",1,--(INDEX(_xlpm.b,,1)=_xlpm.tp)),_xlpm.om,IF(_xlpm.mk="Todas",1,--(INDEX(_xlpm.b,,7)=_xlpm.mk)),_xlpm.od,IF(_xlpm.dp="Todos",1,--(INDEX(_xlpm.b,,4)=_xlpm.dp)),_xlpm.os,IF(_xlpm.st="Todos",1,--(INDEX(_xlpm.b,,10)=_xlpm.st)),_xlpm.ok,_xlpm.oq*_xlpm.ot*_xlpm.om*_xlpm.od*_xlpm.os,SUM(--_xlpm.ok*--(INDEX(_xlpm.b,,1)="Desktop")))} -> 196 | G10: {=_xlfn.LET(_xlpm.q,TRIM($B$4),_xlpm.tp,$A$7,_xlpm.mk,$D$7,_xlpm.dp,$G$7,_xlpm.st,$J$7,_xlpm.md,$M$7,_xlpm.b,'Índice Equipamentos'!$A$2:$T$563,_xlpm.txt,INDEX(_xlpm.b,,20)&"",_xlpm.oq,IF(_xlpm.q="",1,_xlfn.SWITCH(_xlpm.md,"Exata",LOWER(_xlpm.txt)=LOWER(_xlpm.q),"Começa com",LEFT(LOWER(_xlpm.txt),LEN(_xlpm.q))=LOWER(_xlpm.q),ISNUMBER(SEARCH(_xlpm.q,_xlpm.txt)))),_xlpm.ot,IF(_xlpm.tp="Todos",1,--(INDEX(_xlpm.b,,1)=_xlpm.tp)),_xlpm.om,IF(_xlpm.mk="Todas",1,--(INDEX(_xlpm.b,,7)=_xlpm.mk)),_xlpm.od,IF(_xlpm.dp="Todos",1,--(INDEX(_xlpm.b,,4)=_xlpm.dp)),_xlpm.os,IF(_xlpm.st="Todos",1,--(INDEX(_xlpm.b,,10)=_xlpm.st)),_xlpm.ok,_xlpm.oq*_xlpm.ot*_xlpm.om*_xlpm.od*_xlpm.os,SUM(--_xlpm.ok*--(INDEX(_xlpm.b,,1)="Monitor")))} -> 235 | J10: {=_xlfn.LET(_xlpm.q,TRIM($B$4),_xlpm.tp,$A$7,_xlpm.mk,$D$7,_xlpm.dp,$G$7,_xlpm.st,$J$7,_xlpm.md,$M$7,_xlpm.b,'Índice Equipamentos'!$A$2:$T$563,_xlpm.txt,INDEX(_xlpm.b,,20)&"",_xlpm.oq,IF(_xlpm.q="",1,_xlfn.SWITCH(_xlpm.md,"Exata",LOWER(_xlpm.txt)=LOWER(_xlpm.q),"Começa com",LEFT(LOWER(_xlpm.txt),LEN(_xlpm.q))=LOWER(_xlpm.q),ISNUMBER(SEARCH(_xlpm.q,_xlpm.txt)))),_xlpm.ot,IF(_xlpm.tp="Todos",1,--(INDEX(_xlpm.b,,1)=_xlpm.tp)),_xlpm.om,IF(_xlpm.mk="Todas",1,--(INDEX(_xlpm.b,,7)=_xlpm.mk)),_xlpm.od,IF(_xlpm.dp="Todos",1,--(INDEX(_xlpm.b,,4)=_xlpm.dp)),_xlpm.os,IF(_xlpm.st="Todos",1,--(INDEX(_xlpm.b,,10)=_xlpm.st)),_xlpm.ok,_xlpm.oq*_xlpm.ot*_xlpm.om*_xlpm.od*_xlpm.os,SUM(--_xlpm.ok)-SUM(--_xlpm.ok*--(INDEX(_xlpm.b,,1)="Desktop"))-SUM(--_xlpm.ok*--(INDEX(_xlpm.b,,1)="Monitor")))} -> -430 | M10: {=_xlfn.LET(_xlpm.q,TRIM($B$4),_xlpm.tp,$A$7,_xlpm.mk,$D$7,_xlpm.dp,$G$7,_xlpm.st,$J$7,_xlpm.md,$M$7,_xlpm.b,'Índice Equipamentos'!$A$2:$T$563,_xlpm.txt,INDEX(_xlpm.b,,20)&"",_xlpm.oq,IF(_xlpm.q="",1,_xlfn.SWITCH(_xlpm.md,"Exata",LOWER(_xlpm.txt)=LOWER(_xlpm.q),"Começa com",LEFT(LOWER(_xlpm.txt),LEN(_xlpm.q))=LOWER(_xlpm.q),ISNUMBER(SEARCH(_xlpm.q,_xlpm.txt)))),_xlpm.ot,IF(_xlpm.tp="Todos",1,--(INDEX(_xlpm.b,,1)=_xlpm.tp)),_xlpm.om,IF(_xlpm.mk="Todas",1,--(INDEX(_xlpm.b,,7)=_xlpm.mk)),_xlpm.od,IF(_xlpm.dp="Todos",1,--(INDEX(_xlpm.b,,4)=_xlpm.dp)),_xlpm.os,IF(_xlpm.st="Todos",1,--(INDEX(_xlpm.b,,10)=_xlpm.st)),_xlpm.ok,_xlpm.oq*_xlpm.ot*_xlpm.om*_xlpm.od*_xlpm.os,IFERROR(ROWS(_xlfn.UNIQUE(_xlfn._xlws.FILTER(INDEX(_xlpm.b,,3),_xlpm.ok*(INDEX(_xlpm.b,,3)<>"Sem responsável")))),0))} -> 118 | X10: Mesa digitalizadora | Y10: FG | Z10: Cartucheira
X11: Monitor | Y11: Genérico | Z11: Comercial
X12: Notebook | Y12: Grandstream | Z12: Contabilidade
A13: RESULTADO DETALHADO — TODOS OS DADOS DISPONÍVEIS DO EQUIPAMENTO | X13: Telefonia | Y13: HP | Z13: Controladoria
A14: EQUIPAMENTO | B14: RESPONSÁVEL | C14: DEPARTAMENTO | D14: CLASSIFICAÇÃO | E14: MODELO | F14: MARCA | G14: PATRIMÔNIO | H14: HOSTNAME / Nº | I14: STATUS | J14: CONDIÇÃO | K14: CPU / PROCESSADOR | L14: ARMAZENAMENTO | M14: RAM | N14: DETALHES TÉCNICOS | O14: LOCALIZAÇÃO | Y14: Iphone 7 | Z14: Copa
A15: {=_xlfn.LET(_xlpm.q,TRIM($B$4),_xlpm.tp,$A$7,_xlpm.mk,$D$7,_xlpm.dp,$G$7,_xlpm.st,$J$7,_xlpm.md,$M$7,_xlpm.b,'Índice Equipamentos'!$A$2:$T$563,_xlpm.txt,INDEX(_xlpm.b,,20)&"",_xlpm.oq,IF(_xlpm.q="",1,_xlfn.SWITCH(_xlpm.md,"Exata",LOWER(_xlpm.txt)=LOWER(_xlpm.q),"Começa com",LEFT(LOWER(_xlpm.txt),LEN(_xlpm.q))=LOWER(_xlpm.q),ISNUMBER(SEARCH(_xlpm.q,_xlpm.txt)))),_xlpm.ot,IF(_xlpm.tp="Todos",1,--(INDEX(_xlpm.b,,1)=_xlpm.tp)),_xlpm.om,IF(_xlpm.mk="Todas",1,--(INDEX(_xlpm.b,,7)=_xlpm.mk)),_xlpm.od,IF(_xlpm.dp="Todos",1,--(INDEX(_xlpm.b,,4)=_xlpm.dp)),_xlpm.os,IF(_xlpm.st="Todos",1,--(INDEX(_xlpm.b,,10)=_xlpm.st)),_xlpm.ok,_xlpm.oq*_xlpm.ot*_xlpm.om*_xlpm.od*_xlpm.os,_xlpm.v,_xlfn.CHOOSECOLS(_xlpm.b,1,3,4,5,6,7,8,9,10,11,12,13,14,17,19),_xlfn._xlws.FILTER(IF(_xlpm.v="","",_xlpm.v),_xlpm.ok,"Nenhum equipamento encontrado com os filtros selecionados."))} -> #VALUE! | Y15: Leader Electronics | Z15: Dallet
Y16: LG | Z16: Depósito do RH
Y17: LG K10 (2016) | Z17: Depósito RH
Y18: LG K10 (2017) | Z18: Diretoria Administrativa
Y19: Mass Power | Z19: Diretoria Comercial
Y20: Motorol G8 | Z20: Diretoria Exec
Y21: NOC | Z21: Diretoria Executiva
Y22: Nokia | Z22: DIRETORIA EXECUTIVA
Y23: Samsung | Z23: Diretoria Ins
Y24: SWITCHING ADAPTOR | Z24: Diretoria Institucional
Y25: Vasata | Z25: Financeiro
Y26: Wacom | Z26: frente do swicher
Y27: XEROX | Z27: Frente Switcher
Z28: FTP
Z29: Geração
Z30: Gerencia Op/Eg
Z31: Gerencia Op/Eng
Z32: ILHA 1
Z33: ILHA 2
Z34: ILHA 3
Z35: ILHA 4
Z36: Jornalismo
Z37: Marketing
Z38: Master
Z39: Meet
... Z65: TI

Sheet CENTRAL
A1: INVENTARIO DO T.I
A4: TOTAL DE ATIVOS | D4: DEPARTAMENTOS | G4: COM RESPONSÁVEL | J4: COM HOSTNAME
A5: =ROWS(ListaInventario[Categoria]) -> 513 | D5: {=_xlfn.LET(_xlpm.d,TRIM(ListaInventario[Departamento]),COUNTA(_xlfn.UNIQUE(_xlfn._xlws.FILTER(_xlpm.d,_xlpm.d<>""))))} -> 56 | G5: =COUNTIF(ListaInventario[Responsável],"<>") -> 505 | J5: =COUNTIF(ListaInventario[Hostname],"<>") -> 343

Sheet controle
A1: Categoria | B1: Modelo | C1: Hostname | D1: Patrimônio | E1: Departamento | F1: Responsável | G1: Marca | H1: Serial | I1: Ramal | J1: IP | K1: Observação | L1: CPU | M1: Disco | N1: RAM | O1: ISO | P1: Status | Q1: Chave de auditoria | R1: VERIFICAÇÃO | S1: Departamento
A2: Desktop Antigo | B2: Optiplex 7020 | C2: FFF2GN2 | E2: Depósito RH | F2: T.I | G2: Dell | K2: Status: inativo | L2: Intel i7 7ª | M2: NVMe 256 GB | N2: 8 GB | O2: w10 | P2: OK | Q2: =A2&"¦"&B2&"¦"&C2&"¦"&D2&"¦"&E2&"¦"&F2&"¦"&G2&"¦"&#REF!&"¦"&L2&"¦"&M2&"¦"&N2&"¦"&O2&"¦"&#REF! -> #REF! | R2: 46266
A3: Desktop Antigo | B3: Optiplex 7020 | C3: FFLTDN2 | E3: Depósito RH | F3: T.I | G3: Dell | K3: Status: Bom | L3: Intel i7 7ª | M3: NVMe 256 GB | N3: 8 GB | O3: w10 | P3: OK | Q3: =A3&"¦"&B3&"¦"&C3&"¦"&D3&"¦"&E3&"¦"&F3&"¦"&G3&"¦"&K3&"¦"&L3&"¦"&M3&"¦"&N3&"¦"&O3&"¦"&#REF! -> #REF! | R3: 46266
A4: Desktop Antigo | B4: Optiplex 7020 | C4: FFNZDN2 | E4: Depósito RH | F4: T.I | G4: Dell | K4: Status : OK | L4: Intel i7 7ª | M4: NVMe 256 GB | N4: 8 GB | O4: w10 | P4: OK | Q4: =A4&"¦"&B4&"¦"&C4&"¦"&D4&"¦"&E4&"¦"&F4&"¦"&G4&"¦"&K4&"¦"&L4&"¦"&M4&"¦"&N4&"¦"&O4&"¦"&#REF! -> #REF! | R4: 46266
A5: Desktop Antigo | B5: Optiplex 7020 | C5: FFQYDN2 | E5: Depósito RH | F5: T.I | G5: Dell | K5: Status : OK | L5: Intel i7 7ª | M5: NVMe 256 GB | N5: 8 GB | O5: w10 | P5: OK | Q5: =A5&"¦"&B5&"¦"&C5&"¦"&D5&"¦"&E5&"¦"&F5&"¦"&G5&"¦"&K5&"¦"&L5&"¦"&M5&"¦"&N5&"¦"&O5&"¦"&#REF! -> #REF! | R5: 46266
A6: Desktop Antigo | B6: Optiplex 7020 | C6: FFVZDN2 | E6: Depósito RH | F6: T.I | G6: Dell | K6: Status : OK | L6: Intel i7 7ª | M6: NVMe 256 GB | N6: 8 GB | O6: w10 | P6: OK | Q6: =A6&"¦"&B6&"¦"&C6&"¦"&D6&"¦"&E6&"¦"&F6&"¦"&G6&"¦"&K6&"¦"&L6&"¦"&M6&"¦"&N6&"¦"&O6&"¦"&#REF! -> #REF! | R6: 46266
A7: Desktop Antigo | B7: Optiplex 7020 | C7: FFXYDN2 | E7: Depósito RH | F7: T.I | G7: Dell | K7: Status : OK | L7: Intel i7 7ª | M7: NVMe 256 GB | N7: 8 GB | O7: w10 | P7: OK | Q7: =A7&"¦"&B7&"¦"&C7&"¦"&D7&"¦"&E7&"¦"&F7&"¦"&G7&"¦"&K7&"¦"&L7&"¦"&M7&"¦"&N7&"¦"&O7&"¦"&#REF! -> #REF! | R7: 46266
A8: Desktop Antigo | B8: Optiplex 7020 | C8: FFZYDN2 | E8: Depósito RH | F8: T.I | G8: Dell | K8: Status : OK | L8: Intel i7 7ª | M8: NVMe 256 GB | N8: 8 GB | O8: w10 | P8: OK | Q8: =A8&"¦"&B8&"¦"&C8&"¦"&D8&"¦"&E8&"¦"&F8&"¦"&G8&"¦"&K8&"¦"&L8&"¦"&M8&"¦"&N8&"¦"&O8&"¦"&#REF! -> #REF! | R8: 46266
A9: Desktop Antigo | B9: Optiplex 7020 | C9: FG30FN2 | E9: Depósito RH | F9: T.I | G9: Dell | K9: Status : OK | L9: Intel i7 7ª | M9: NVMe 256 GB | N9: 8 GB | O9: w10 | P9: OK | Q9: =A9&"¦"&B9&"¦"&C9&"¦"&D9&"¦"&E9&"¦"&F9&"¦"&G9&"¦"&K9&"¦"&L9&"¦"&M9&"¦"&N9&"¦"&O9&"¦"&#REF! -> #REF! | R9: 46266
A10: Desktop Antigo | B10: Optiplex 7020 | C10: FG5ZDN2 | E10: Depósito RH | F10: T.I | G10: Dell | K10: Status : OK | L10: Intel i7 7ª | M10: NVMe 256 GB | N10: 8 GB | O10: w10 | P10: OK | Q10: =A10&"¦"&B10&"¦"&C10&"¦"&D10&"¦"&E10&"¦"&F10&"¦"&G10&"¦"&K10&"¦"&L10&"¦"&M10&"¦"&N10&"¦"&O10&"¦"&#REF! -> #REF! | R10: 46266
A11: Desktop Antigo | B11: Optiplex 7020 | C11: FG7YDN2 | E11: Depósito RH | F11: T.I | G11: Dell | K11: Status : OK | L11: Intel i7 7ª | M11: SSD SATA 256 GB | N11: 8 GB | O11: w10 | P11: OK | Q11: =A11&"¦"&B11&"¦"&C11&"¦"&D11&"¦"&E11&"¦"&F11&"¦"&G11&"¦"&K11&"¦"&L11&"¦"&M11&"¦"&N11&"¦"&O11&"¦"&#REF! -> #REF! | R11: 46266
A12: Desktop Antigo | B12: Optiplex 7020 | C12: FGDTDN2 | E12: Depósito RH | F12: T.I | G12: Dell | K12: Status : OK | L12: Intel i7 7ª | M12: NVMe 256 GB | N12: 8 GB | O12: w10 | P12: OK | Q12: =A12&"¦"&B12&"¦"&C12&"¦"&D12&"¦"&E12&"¦"&F12&"¦"&G12&"¦"&K12&"¦"&L12&"¦"&M12&"¦"&N12&"¦"&O12&"¦"&#REF! -> #REF! | R12: 46266
A13: Desktop Antigo | B13: 7050 | C13: FGGYDN2 | E13: Depósito RH | F13: T.I | G13: Dell | K13: Status : OK | P13: OK | Q13: =A13&"¦"&B13&"¦"&C13&"¦"&D13&"¦"&E13&"¦"&F13&"¦"&G13&"¦"&K13&"¦"&L13&"¦"&M13&"¦"&N13&"¦"&O13&"¦"&#REF! -> #REF! | R13: 46266
A14: Desktop Antigo | B14: Optiplex 7020 | C14: FGJ1FN2 | E14: Depósito RH | F14: T.I | G14: Dell | K14: Status : OK | L14: Intel i7 7ª | M14: NVMe 256 GB | N14: 8 GB | O14: w10 | P14: OK | Q14: =A14&"¦"&B14&"¦"&C14&"¦"&D14&"¦"&E14&"¦"&F14&"¦"&G14&"¦"&K14&"¦"&L14&"¦"&M14&"¦"&N14&"¦"&O14&"¦"&#REF! -> #REF! | R14: 46266
A15: Desktop Antigo | B15: Optiplex 7020 | C15: FGK2FN2 | E15: Depósito RH | F15: T.I | G15: Dell | K15: Status : OK | L15: Intel i7 7ª | M15: NVMe 256 GB | N15: 8 GB | O15: w10 | P15: OK | Q15: =A15&"¦"&B15&"¦"&C15&"¦"&D15&"¦"&E15&"¦"&F15&"¦"&G15&"¦"&K15&"¦"&L15&"¦"&M15&"¦"&N15&"¦"&O15&"¦"&#REF! -> #REF! | R15: 46266
A16: Desktop Antigo | B16: Optiplex 7020 | C16: FGLZDN2 | E16: Depósito RH | F16: T.I | G16: Dell | K16: Status : OK | L16: Intel i7 7ª | M16: NVMe 256 GB | N16: 8 GB | O16: w10 | P16: OK | Q16: =A16&"¦"&B16&"¦"&C16&"¦"&D16&"¦"&E16&"¦"&F16&"¦"&G16&"¦"&K16&"¦"&L16&"¦"&M16&"¦"&N16&"¦"&O16&"¦"&#REF! -> #REF! | R16: 46266
A17: Desktop Antigo | B17: Optiplex 7020 | C17: FGNTDN2 | E17: Depósito RH | F17: T.I | G17: Dell | K17: Status : INATIVO | L17: Intel i7 7ª | M17: NVMe 256 GB | N17: 8 GB | O17: w10 | P17: OK | Q17: =A17&"¦"&B17&"¦"&C17&"¦"&D17&"¦"&E17&"¦"&F17&"¦"&G17&"¦"&#REF!&"¦"&L17&"¦"&M17&"¦"&N17&"¦"&O17&"¦"&#REF! -> #REF! | R17: 46266
A18: Desktop Antigo | B18: Optiplex 7020 | C18: FGQ2FN2 | E18: Depósito RH | F18: T.I | G18: Dell | K18: Status : OK | L18: Intel i7 7ª | M18: NVMe 256 GB | N18: 8 GB | O18: w10 | P18: OK | Q18: =A18&"¦"&B18&"¦"&C18&"¦"&D18&"¦"&E18&"¦"&F18&"¦"&G18&"¦"&K18&"¦"&L18&"¦"&M18&"¦"&N18&"¦"&O18&"¦"&#REF! -> #REF! | R18: 46266
A19: Desktop Antigo | B19: Optiplex 7020 | C19: FGRZDN2 | E19: Depósito RH | F19: T.I | G19: Dell | K19: Status : OK | L19: Intel i7 7ª | M19: NVMe 256 GB | N19: 8 GB | O19: w10 | P19: OK | Q19: =A19&"¦"&B19&"¦"&C19&"¦"&D19&"¦"&E19&"¦"&F19&"¦"&G19&"¦"&K19&"¦"&L19&"¦"&M19&"¦"&N19&"¦"&O19&"¦"&#REF! -> #REF! | R19: 46266
A20: Desktop Antigo | B20: Optiplex 7020 | C20: FGT1FN2 | E20: Depósito RH | F20: T.I | G20: Dell | K20: Status : OK | L20: Intel i7 7ª | M20: NVMe 256 GB | N20: 8 GB | O20: w10 | P20: OK | Q20: =A20&"¦"&B20&"¦"&C20&"¦"&D20&"¦"&E20&"¦"&F20&"¦"&G20&"¦"&K20&"¦"&L20&"¦"&M20&"¦"&N20&"¦"&O20&"¦"&#REF! -> #REF! | R20: 46266
A21: Desktop Antigo | B21: Optiplex 7020 | C21: FGV2FN2 | E21: Depósito RH | F21: T.I | G21: Dell | K21: Status : OK | L21: Intel i7 7ª | M21: NVMe 256 GB | N21: 8 GB | O21: w10 | P21: OK | Q21: =A21&"¦"&B21&"¦"&C21&"¦"&D21&"¦"&E21&"¦"&F21&"¦"&G21&"¦"&#REF!&"¦"&L21&"¦"&M21&"¦"&N21&"¦"&O21&"¦"&#REF! -> #REF! | R21: 46266
A22: Desktop Antigo | B22: Optiplex 7020 | C22: FGX0FN2 | E22: Depósito RH | F22: T.I | G22: Dell | K22: Status : OK | L22: Intel i7 7ª | M22: NVMe 256 GB | N22: 8 GB | O22: w10 | P22: OK | Q22: =A22&"¦"&B22&"¦"&C22&"¦"&D22&"¦"&E22&"¦"&F22&"¦"&G22&"¦"&K22&"¦"&L22&"¦"&M22&"¦"&N22&"¦"&O22&"¦"&#REF! -> #REF! | R22: 46266
A23: Desktop Antigo | B23: Optiplex 7020 | C23: FGZ0FN2 | E23: Depósito RH | F23: T.I | G23: Dell | K23: Status : OK | L23: Intel i7 7ª | M23: NVMe 256 GB | N23: 8 GB | O23: w10 | P23: OK | Q23: =A23&"¦"&B23&"¦"&C23&"¦"&D23&"¦"&E23&"¦"&F23&"¦"&G23&"¦"&K23&"¦"&L23&"¦"&M23&"¦"&N23&"¦"&O23&"¦"&#REF! -> #REF! | R23: 46266
A24: Desktop Antigo | B24: Optiplex 7020 | C24: FH3ZDN2 | E24: Depósito RH | F24: T.I | G24: Dell | K24: Status : OK | L24: Intel i7 7ª | M24: NVMe 256 GB | N24: 8 GB | O24: w10 | P24: OK | Q24: =A24&"¦"&B24&"¦"&C24&"¦"&D24&"¦"&E24&"¦"&F24&"¦"&G24&"¦"&K24&"¦"&L24&"¦"&M24&"¦"&N24&"¦"&O24&"¦"&#REF! -> #REF! | R24: 46266
A25: Desktop Antigo | B25: Optiplex 7020 | C25: FH90FN2 | E25: Depósito RH | F25: T.I | G25: Dell | K25: Status : OK | P25: OK | Q25: =A25&"¦"&B25&"¦"&C25&"¦"&D25&"¦"&E25&"¦"&F25&"¦"&G25&"¦"&K25&"¦"&L25&"¦"&M25&"¦"&N25&"¦"&O25&"¦"&#REF! -> #REF! | R25: 46266
A26: Desktop Antigo | B26: Optiplex 7020 | C26: FHC0FN2 | E26: Depósito RH | F26: T.I | G26: Dell | K26: Status : OK | L26: Intel i7 7ª | M26: SSD SATA 256 GB | N26: 8 GB | O26: w10 | P26: OK | Q26: =A26&"¦"&B26&"¦"&C26&"¦"&D26&"¦"&E26&"¦"&F26&"¦"&G26&"¦"&K26&"¦"&L26&"¦"&M26&"¦"&N26&"¦"&O26&"¦"&#REF! -> #REF! | R26: 46266
A27: Desktop Antigo | B27: Optiplex 7020 | C27: FHD0FN2 | E27: Depósito RH | F27: T.I | G27: Dell | K27: Status : OK | L27: Intel i7 7ª | M27: NVMe 256 GB | N27: 8 GB | O27: w10 | P27: OK | Q27: =A27&"¦"&B27&"¦"&C27&"¦"&D27&"¦"&E27&"¦"&F27&"¦"&G27&"¦"&K27&"¦"&L27&"¦"&M27&"¦"&N27&"¦"&O27&"¦"&#REF! -> #REF! | R27: 46266
A28: Desktop Antigo | B28: Optiplex 7020 | C28: FHDYFN2 | E28: Depósito RH | F28: T.I | G28: Dell | K28: Status : OK | L28: Intel i7 7ª | M28: NVMe 256 GB | N28: 8 GB | O28: w10 | P28: OK | Q28: =A28&"¦"&B28&"¦"&C28&"¦"&D28&"¦"&E28&"¦"&F28&"¦"&G28&"¦"&K28&"¦"&L28&"¦"&M28&"¦"&N28&"¦"&O28&"¦"&#REF! -> #REF! | R28: 46266
A29: Desktop Antigo | B29: Optiplex 7020 | C29: FHFZDN2 | E29: Depósito RH | F29: T.I | G29: Dell | K29: Status : OK | L29: Intel i7 7ª | M29: NVMe 256 GB | N29: 8 GB | O29: w10 | P29: OK | Q29: =A29&"¦"&B29&"¦"&C29&"¦"&D29&"¦"&E29&"¦"&F29&"¦"&G29&"¦"&K29&"¦"&L29&"¦"&M29&"¦"&N29&"¦"&O29&"¦"&#REF! -> #REF! | R29: 46266
A30: Desktop Antigo | B30: Optiplex 7020 | C30: FHH2FN2 | E30: Depósito RH | F30: T.I | G30: Dell | K30: Status : OK | P30: OK | Q30: =A30&"¦"&B30&"¦"&C30&"¦"&D30&"¦"&E30&"¦"&F30&"¦"&G30&"¦"&K30&"¦"&L30&"¦"&M30&"¦"&N30&"¦"&O30&"¦"&#REF! -> #REF! | R30: 46266
A31: Desktop Antigo | B31: Optiplex 7020 | C31: FHJTDN2 | E31: Depósito RH | F31: T.I | G31: Dell | K31: Status : OK | L31: Intel i7 7ª | M31: SSD SATA 256 GB | N31: 8 GB | O31: w10 | P31: OK | Q31: =A31&"¦"&B31&"¦"&C31&"¦"&D31&"¦"&E31&"¦"&F31&"¦"&G31&"¦"&K31&"¦"&L31&"¦"&M31&"¦"&N31&"¦"&O31&"¦"&#REF! -> #REF! | R31: 46266
A32: Desktop Antigo | B32: Optiplex 7020 | C32: FHKYDN2 | E32: Depósito RH | F32: T.I | G32: Dell | K32: Status : OK | L32: Intel i7 7ª | M32: SSD SATA 256 GB | N32: 8 GB | O32: w10 | P32: OK | Q32: =A32&"¦"&B32&"¦"&C32&"¦"&D32&"¦"&E32&"¦"&F32&"¦"&G32&"¦"&K32&"¦"&L32&"¦"&M32&"¦"&N32&"¦"&O32&"¦"&#REF! -> #REF! | R32: 46266
A33: Desktop Antigo | B33: Optiplex 7020 | C33: FHM0FN2 | E33: Depósito RH | F33: T.I | G33: Dell | K33: Status : OK | L33: Intel i7 7ª | M33: NVMe 256 GB | N33: 8 GB | O33: w10 | P33: OK | Q33: =A33&"¦"&B33&"¦"&C33&"¦"&D33&"¦"&E33&"¦"&F33&"¦"&G33&"¦"&K33&"¦"&L33&"¦"&M33&"¦"&N33&"¦"&O33&"¦"&#REF! -> #REF! | R33: 46266
A34: Desktop Antigo | B34: Optiplex 7020 | C34: FHNZDN2 | E34: Depósito RH | F34: T.I | G34: Dell | K34: Status : OK | L34: Intel i7 7ª | M34: NVMe 256 GB | N34: 8 GB | O34: w10 | P34: OK | Q34: =A34&"¦"&B34&"¦"&C34&"¦"&D34&"¦"&E34&"¦"&F34&"¦"&G34&"¦"&K34&"¦"&L34&"¦"&M34&"¦"&N34&"¦"&O34&"¦"&#REF! -> #REF! | R34: 46266
A35: Desktop Antigo | B35: Optiplex 7020 | C35: FHQTDN2 | E35: Depósito RH | F35: T.I | G35: Dell | K35: Status : OK | L35: Intel i7 7ª | M35: NVMe 256 GB | N35: 8 GB | O35: w10 | P35: OK | Q35: =A35&"¦"&B35&"¦"&C35&"¦"&D35&"¦"&E35&"¦"&F35&"¦"&G35&"¦"&K35&"¦"&L35&"¦"&M35&"¦"&N35&"¦"&O35&"¦"&#REF! -> #REF! | R35: 46266
A36: Desktop Antigo | B36: Optiplex 7020 | C36: FHSYDN2 | E36: Depósito RH | F36: T.I | G36: Dell | K36: Status : OK | P36: OK | Q36: =A36&"¦"&B36&"¦"&C36&"¦"&D36&"¦"&E36&"¦"&F36&"¦"&G36&"¦"&K36&"¦"&L36&"¦"&M36&"¦"&N36&"¦"&O36&"¦"&#REF! -> #REF! | R36: 46266
A37: Desktop Antigo | B37: Optiplex 7020 | C37: FHZYDN2 | E37: Depósito RH | F37: T.I | G37: Dell | K37: Status : inativo | L37: Intel i7 7ª | M37: NVMe 256 GB | N37: 8 GB | O37: w10 | P37: OK | Q37: =A37&"¦"&B37&"¦"&C37&"¦"&D37&"¦"&E37&"¦"&F37&"¦"&G37&"¦"&#REF!&"¦"&L37&"¦"&M37&"¦"&N37&"¦"&O37&"¦"&#REF! -> #REF! | R37: 46266
A38: Desktop Antigo | B38: Optiplex 7020 | C38: FKG0FN2 | E38: Depósito RH | F38: T.I | G38: Dell | K38: Status : OK | L38: Intel i7 7ª | M38: NVMe 256 GB | N38: 8 GB | O38: w10 | P38: OK | Q38: =A38&"¦"&B38&"¦"&C38&"¦"&D38&"¦"&E38&"¦"&F38&"¦"&G38&"¦"&K38&"¦"&L38&"¦"&M38&"¦"&N38&"¦"&O38&"¦"&#REF! -> #REF! | R38: 46266
A39: Desktop Antigo | B39: Optiplex 7020 | C39: FKHZDN2 | E39: Depósito RH | F39: T.I | G39: Dell | K39: Status : OK | L39: Intel i7 7ª | M39: NVMe 256 GB | N39: 8 GB | O39: w10 | P39: OK | Q39: =A39&"¦"&B39&"¦"&C39&"¦"&D39&"¦"&E39&"¦"&F39&"¦"&G39&"¦"&K39&"¦"&L39&"¦"&M39&"¦"&N39&"¦"&O39&"¦"&#REF! -> #REF! | R39: 46266
A40: Desktop Antigo | B40: Optiplex 7020 | C40: FKJ0FN2 | E40: Depósito RH | F40: T.I | G40: Dell | K40: Status : OK | L40: Intel i7 7ª | M40: NVMe 256 GB | N40: 8 GB | O40: w10 | P40: OK | Q40: =A40&"¦"&B40&"¦"&C40&"¦"&D40&"¦"&E40&"¦"&F40&"¦"&G40&"¦"&K40&"¦"&L40&"¦"&M40&"¦"&N40&"¦"&O40&"¦"&#REF! -> #REF! | R40: 46266
...

Sheet Monitores
A1: Configurações | B1: Modelo | C1: Numero | D1: Patrimonio | E1: Departamento | F1: Nomes | G1: MARCA
A2: Monitor 18.5”, HD , 60Hz | B2: 9P1E | C2: 001 | D2: 439 | F2: JOÃO OTÁVIO | G2: Dell
A3: Monitor 18.5”, HD , 60Hz | B3: 9P1E | C3: 002 | D3: 455 | F3: JOÃO OTÁVIO | G3: Dell
A4: Monitor 18.5”, HD , 60Hz | B4: 9P1E | C4: 003 | D4: 668 | E4: Administrativo | F4: AMANDA PACHECO | G4: Dell
A5: Monitor 18.5”, HD , 60Hz | B5: 9P1E | C5: 004 | D5: 677 | E5: Administrativo | F5: AMANDA PACHECO | G5: Dell
A6: Monitor 18.5”, HD , 60Hz | B6: 9P1E | C6: 005 | D6: 663 | E6: Administrativo | F6: SABRINA | G6: Dell
A7: Monitor 18.5”, HD , 60Hz | B7: 9P1E | C7: 006 | D7: 664 | E7: Administrativo | F7: SABRINA | G7: Dell
A8: Monitor 18.5”, HD , 60Hz | B8: 9P1E | C8: 007 | D8: 683 | E8: Administrativo | F8: DAISY | G8: Dell
A9: Monitor 18.5”, HD , 60Hz | B9: 9P1E | C9: 008 | D9: 681 | E9: Administrativo | F9: DAISY | G9: Dell
A10: Monitor 18.5”, HD , 60Hz | B10: 9P1E | C10: 009 | D10: 667 | E10: Administrativo | F10: ADRIANO RESTA | G10: Dell
A11: Monitor 18.5”, HD , 60Hz | B11: 9P1E | C11: 010 | D11: 676 | E11: Administrativo | F11: ADRIANO RESTA | G11: Dell
A12: Monitor 21.5'', FHD , 75Hz | B12: 22B3HMF | C12: 011 | D12: 720 | E12: T.I | F12: BRUNO | G12: Dell
A13: Monitor 21.5'', FHD , 75Hz | B13: 22B3HMF | C13: 012 | D13: 726 | E13: T.I | F13: BRUNO | G13: Dell
A14: Monitor 18.5”, HD , 60Hz | B14: 9P1E | C14: 013 | D14: 424 | E14: T.I | F14: AMAILSON GAWLINSKI | G14: Dell
A15: Monitor 18.5”, HD , 60Hz | B15: 9P1E | C15: 014 | D15: 413 | E15: T.I | F15: AMAILSON GAWLINSKI | G15: Dell
A16: Monitor 18.5”, HD , 60Hz | B16: 9P1E | C16: 015 | D16: 691 | E16: T.I | F16: LIVRE | G16: Dell
A17: Monitor 18.5”, HD , 60Hz | B17: 9P1E | C17: 016 | D17: 426 | E17: T.I | F17: LIVRE | G17: Dell
A18: Monitor 18.5”, HD , 60Hz | B18: 9P1E | C18: 017 | D18: 666 | E18: Controladoria | F18: CLAUDIA | G18: Dell
A19: Monitor 18.5”, HD , 60Hz | B19: 9P1E | C19: 018 | D19: 669 | E19: Controladoria | F19: CLAUDIA | G19: Dell
A20: Monitor 23" , FHD , 60Hz | B20: P2317H | C20: 019 | D20: 88P5GL2 | E20: Dallet | F20: TIAGO NARDON | G20: Dell
A21: Monitor 23" , FHD , 60Hz | B21: P2317H | C21: 020 | D21: 50G5GL2 | E21: Dallet | F21: TIAGO NARDON | G21: Dell
A22: Monitor 18.5”, HD , 60Hz | B22: 9P1E | C22: 021 | D22: 420 | E22: Contabilidade | F22: SUSI | G22: Dell
A23: Monitor 18.5”, HD , 60Hz | B23: 9P1E | C23: 022 | D23: 438 | E23: Contabilidade | F23: SUSI | G23: Dell
A24: Monitor 18.5”, HD , 60Hz | B24: 9P1E | C24: 023 | D24: 440 | E24: Contabilidade | F24: VALDIR | G24: Dell
A25: Monitor 18.5”, HD , 60Hz | B25: 9P1E | C25: 024 | D25: 442 | E25: Contabilidade | F25: VALDIR | G25: Dell
A26: Monitor 18.5”, HD , 60Hz | B26: 9P1E | C26: 025 | D26: 415 | E26: Financeiro | F26: DEBORA | G26: Dell
A27: Monitor 18.5”, HD , 60Hz | B27: 9P1E | C27: 026 | D27: 427 | E27: Financeiro | F27: DEBORA | G27: Dell
A28: Monitor 18.5”, HD , 60Hz | B28: 9P1E | C28: 027 | D28: 447 | E28: Financeiro | F28: GUILHERME | G28: Dell
A29: Monitor 18.5”, HD , 60Hz | B29: 9P1E | C29: 028 | D29: 432 | E29: Financeiro | F29: GUILHERME | G29: Dell
A30: Monitor 18.5”, HD , 60Hz | B30: 9P1E | C30: 029 | D30: 429 | E30: Financeiro | F30: DEBORA | G30: Dell
A31: Monitor 18.5”, HD , 60Hz | B31: 9P1E | C31: 030 | D31: 450 | E31: Financeiro | F31: DEBORA | G31: Dell
A32: Monitor 18.5”, HD , 60Hz | B32: 9P1E | C32: 031 | D32: 684 | E32: Opec | F32: DUDA | G32: Dell
A33: Monitor 18.5”, HD , 60Hz | B33: 9P1E | C33: 032 | D33: 675 | E33: Opec | F33: DUDA | G33: Dell
A34: Monitor 18.5”, HD , 60Hz | B34: 9P1E | C34: 033 | D34: 678 | E34: Opec | F34: VITOR | G34: Dell
A35: Monitor 18.5”, HD , 60Hz | B35: 9P1E | C35: 034 | D35: 673 | E35: Opec | F35: VITOR | G35: Dell
A36: Monitor 21.5'', FHD, 75HZ | B36: 22B3HMF | C36: 035 | D36: 724 | E36: Marketing | F36: TIAGO PERONI | G36: Dell
A37: Monitor 21.5'', FHD, 75HZ | B37: 22B3HMF | C37: 036 | D37: 717 | E37: Marketing | F37: TIAGO PERONI | G37: Dell
A38: Monitor 23" , FHD , 60Hz | B38: Dell P2317H | C38: 037 | D38: 51K5GL2 | E38: Marketing | F38: RODRIGO CHAGAS | G38: Dell
A39: Monitor 23" , FHD , 60Hz | B39: Dell P2317H | C39: 038 | D39: 6K05GL2 | E39: Marketing | F39: RODRIGO CHAGAS | G39: Dell
A40: Monitor 21.5'', FHD, 75HZ | B40: 22B3HMF | C40: 039 | D40: 711 | E40: Marketing | F40: TIAGO FERREIRA | G40: Dell
...

Sheet Responsável
A1: NOME | B1: CARGO | C1: SETOR
A2: PATRICIA INES BALDASSO | B2: Advogado | C2: Juridico
A3: LEANDRO MARTINS BONES | B3: Almoxarife Técnico | C3: Operacional
A4: MAURECI FERREIRA PIRES | B4: Almoxarife Técnico | C4: Operacional
A5: PAULO DA SILVA BANDEIRA | B5: Almoxarife Técnico | C5: Operacional
A6: AMANDA GOMES PACHECO SEVERO | B6: Analista Administrativo(a) | C6: Administração
A7: DAISY DA SILVA RUSSO | B7: Analista Administrativo(a) | C7: Administração
A8: SABRINA CARVALHO DA SILVA | B8: Analista Administrativo(a) | C8: Administração
A9: FABIANA ALMINHANA | B9: Analista Comercial | C9: Comercial
A10: ISABEL CRISTINA GIUSTI DA SILVA | B10: Analista Comercial | C10: Comercial
A11: SUSI SILVETE DA SILVA | B11: Analista Contábil | C11: Contabilidade
A12: RODRIGO CHAGAS FREITAS | B12: Analista de Criação | C12: Marketing
... A177: THIAGO COSTA NARDON | B177: Técnico de Manutenção TV | C177: Técnica

Sheet celular 
A1: MARCA | B1: MODELO | C1: RES | D1: PROCESSADOR | E1: RAM | F1: ARMAZENAMENTO | G1: CAMERA | H1: TELA | I1: SISTEMA | J1: DEPARTAMENTO | K1: ESTADO | L1: AVARIA | M1: BATERIA | N1: M/ BATERIA | O1: VOLTAGEM | P1: CAPACIDADE | Q1: Imagem | R1: LINK
A2: LG K10 (2016) | B2: LG-M2-2 | C2: HD (1280 x 720p) | D2: MediaTek MT6753 | E2: 1GB | F2: 16GB | G2: 13MP | H2: 5,3 polegadas, IPS LCD, resolução HD (1280 x 720 pixels), 277 ppi | I2: Android 6.0 | J2: Depósito do RH | K2: OK | L2: alguns arranhões na tela | M2: LG | N2: BL - 45A1H | O2: 3.8V | P2: 2220mAh(8.5Wh) | R2: https://kommodo.ai/i/8tgS2SIJc8RnlNsSLG6I
A3: LG K10 (2016) | B3: LG-M2-2 | C3: HD (1280 x 720p) | D3: MediaTek MT6753 | E3: 1GB | F3: 16GB | G3: 13MP | H3: 5,3 polegadas, IPS LCD, resolução HD (1280 x 720 pixels), 277 ppi | I3: Android 6.0 | J3: Depósito do RH | K3: OK | L3: alguns arranhões na tela | M3: LG | N3: BL - 45A1H | O3: 3.8V | P3: 2220mAh(8.5Wh) | Q3: Imagem inserida | R3: https://kommodo.ai/i/8tgS2SIJc8RnlNsSLG6I
A4: LG K10 (2016) | B4: LG-M2-2 | C4: HD (1280 x 720p) | D4: MediaTek MT6753 | E4: 1GB | F4: 16GB | G4: 13MP | H4: 5,3 polegadas, IPS LCD, resolução HD (1280 x 720 pixels), 277 ppi | I4: Android 6.0 | J4: Depósito do RH | K4: OK | L4: alguns arranhões na tela | M4: LG | N4: BL - 45A1H | O4: 3.8V | P4: 2.220mAh(8.5Wh) | Q4: Imagem inserida | R4: https://kommodo.ai/i/8tgS2SIJc8RnlNsSLG6I
A5: LG K10 (2017) | B5: M250 | C5: HD (720 x 1280 pixels) | D5: MediaTek MT6750 Octa- Core (4x 1.5GHz + 4x 1.0 GHz) | E5: 2GB | F5: 32GB | G5: 13MP (Abertura f/2.2) com Flash LED | H5: 5.3 polegadas, IPS LCD ,Resolução HD (1280 x 720 pixels) | I5: Android 7.0 Nouat | J5: Depósito do RH | K5: RUIM | L5: amarelamento tela quebrada varias partes lascadas | M5: LG | N5: BL-46G1F | O5: 3.85V | P5: 2700mAh | Q5: Imagem inserida | R5: https://kommodo.ai/i/nHaPLmGBovJMLHLOUKfH
A6: LG K10 (2017) | B6: M250 | C6: HD (720 x 1280 pixels) | D6: MediaTek MT6750 Octa- Core (4x 1.5GHz + 4x 1.0 GHz) | E6: 2GB | F6: 32GB | G6: 13MP (Abertura f/2.2) com Flash LED | H6: 5.3 polegadas, IPS LCD ,Resolução HD (1280 x 720 pixels) | I6: Android 7.0 Nouat | J6: Depósito do RH | K6: RUIM | L6: amarelamento tela quebrada varias partes lascadas | M6: LG | N6: BL-46G1F | O6: 3.85V | P6: 2700mAh | Q6: Imagem inserida | R6: https://kommodo.ai/i/nHaPLmGBovJMLHLOUKfH
A7: LG K10 (2017) | B7: M250 | C7: HD (720 x 1280 pixels) | D7: MediaTek MT6750 Octa- Core (4x 1.5GHz + 4x 1.0 GHz) | E7: 2GB | F7: 32GB | G7: 13MP (Abertura f/2.2) com Flash LED | H7: 5.3 polegadas, IPS LCD ,Resolução HD (1280 x 720 pixels) | I7: Android 7.0 Nouat | J7: Depósito do RH | K7: RUIM | L7: amarelamento tela quebrada varias partes lascadas | M7: LG | N7: BL-46G1F | O7: 3.85V | P7: 2700mAh | Q7: Imagem inserida | R7: https://kommodo.ai/i/nHaPLmGBovJMLHLOUKfH
A8: Motorol G8 | B8: XT2019-2 | C8: FULL HD+ ( 1080 x 2280 pixels) | D8: Qualcomm Snapdragon 665 (Octa-Core até 2.0GHz) | E8: 4GB | F8: 64GB | G8: Tripla: 48Mp (principal) + 16Mp ( Câmera de ação ultrawide) + 5MP(profundidade) | H8: IPS LCD de 6,3 polegadas | I8: Android 9.0 Pie (atualizável para Android 10) | J8: Depósito do RH | K8: RUIM | L8: amarelamento tela quebrada camera quebrada muitas partes lascadas | M8: fundo não abre | N8: fundo não abre | O8: fundo não abre | P8: fundo não abre | R8: https://kommodo.ai/i/8Ya9extv8J2wcSP7yTkq
A9: Motorol G8 | B9: XT2019-2 | C9: FULL HD+ ( 1080 x 2280 pixels) | D9: Qualcomm Snapdragon 665 (Octa-Core até 2.0GHz) | E9: 4GB | F9: 64GB | G9: Tripla: 48Mp (principal) + 16Mp ( Câmera de ação ultrawide) + 5MP(profundidade) | H9: IPS LCD de 6,3 polegadas | I9: Android 9.0 Pie (atualizável para Android 10) | J9: Depósito do RH | K9: RUIM | L9: amarelamento tela quebrada camera quebrada muitas partes lascadas | M9: fundo não abre | N9: fundo não abre | O9: fundo não abre | P9: fundo não abre | R9: https://kommodo.ai/i/8Ya9extv8J2wcSP7yTkq
A10: Nokia | B10: C2-01.5 | C10: QVGA (240 x 320 pixels) | D10: 235 MHz ARM9 | E10: 64 MB | F10: 45 a 65 MB internos, expansivel com microSD | G10: 3.2 Megapixels com zoom digital de 4x(sem flash) | H10: LCD TFT de 2.8 polegadas (Resolução: 240 x 320 pixels) | I10: Plataforma Symbian Series 40 (S40) | J10: Depósito do RH | K10: RUIM | L10: partes lascadas partes desgastadas e muitos arranhões | M10: Nokia | N10: BL-5C | O10: 3.7V | P10: 2.8Wh | R10: https://kommodo.ai/i/YhK1Vlol0LJVDobuZAFH
A11: Nokia | B11: C2-01.5 | C11: QVGA (240 x 320 pixels) | D11: 235 MHz ARM9 | E11: 64 MB | F11: 45 a 65 MB internos, expansivel com microSD | G11: 3.2 Megapixels com zoom digital de 4x(sem flash) | H11: LCD TFT de 2.8 polegadas (Resolução: 240 x 320 pixels) | I11: Plataforma Symbian Series 40 (S40) | J11: Depósito do RH | K11: RUIM | L11: partes lascadas partes desgastadas e muitos arranhões | M11: Nokia | N11: BL-5C | O11: 3.7V | P11: 2.8Wh | Q11: Imagem inserida | R11: https://kommodo.ai/i/YhK1Vlol0LJVDobuZAFH
A12: Nokia | B12: C2-01.5 | C12: QVGA (240 x 320 pixels) | D12: 235 MHz ARM9 | E12: 64 MB | F12: 45 a 65 MB internos, expansivel com microSD | G12: 3.2 Megapixels com zoom digital de 4x(sem flash) | H12: LCD TFT de 2.8 polegadas (Resolução: 240 x 320 pixels) | I12: Plataforma Symbian Series 40 (S40) | J12: Depósito do RH | K12: RUIM | L12: partes lascadas partes desgastadas e muitos arranhões | M12: Nokia | N12: BL-5C | O12: 3.7V | P12: 2.8Wh | R12: https://kommodo.ai/i/YhK1Vlol0LJVDobuZAFH
A13: Iphone 7 | C13: 1334 x 750 pixels a 326 ppi (Resolução Retina HD). | D13: Apple A10 Fusion (Quad-core) | E13: 2 GB | F13: 128 GB | G13: 12 MP (Abertura f/1.8) com Estabilização Óptica (OIS) | H13: Retina HD de 4,7 polegadas com tecnologia IPS | I13: iOS 10 | J13: Depósito do RH | K13: OK | L13: sem avarias aparentes | M13: fundo não abre | N13: fundo não abre | O13: fundo não abre | P13: 1.960 mAh | R13: https://kommodo.ai/i/PfWLMPq5pvjbYT4p38G4

Sheet conectores 
A1: MARCA | B1: POTÊNCIA | C1: TEN/E (IN) | D1: TEN/S (OUT) | E1: MODELO | F1: N/DP | G1: FAMILIA ADP | H1: FABRICANTE | I1: OBS | J1: ESTADO | K1: AVARIA | L1: IMAGEM
A2: DELL | B2: 65W | C2: 100-240V~1.6A/50-60Hz (bivolt) | D2: 19.5V ~ 3.34A | E2: LA65NS2-01 | F2: 06TM1C | G2: PA-12 FAMILY | H2: LITE-ON TECHNOLOGY CORPORATION | I2: 1 carregador completo | J2: BOM | K2: Sem avarias aparentes | L2: #VALUE!
A3: DELL | B3: 65W | C3: 100-240V~1.6A/50-60Hz (bivolt) | D3: 19.5V ~ 3.34A | E3: LA65NS2-01 | F3: 06TM1C | G3: PA-12 FAMILY | H3: LITE-ON TECHNOLOGY CORPORATION | I3: Sem cabo de força | J3: BOM | K3: Sem avarias aparentes | L3: #VALUE!
A4: DELL | B4: 65W | C4: 100-240V~1.6A/50-60Hz (bivolt) | D4: 19.5V ~ 3.34A | E4: LA65NS2-01 | F4: 06TM1C | G4: PA-12 FAMILY | H4: LITE-ON TECHNOLOGY CORPORATION | I4: 1 carregador completo - c/adaptador | J4: BOM | K4: Sem avarias aparentes | L4: #VALUE!
A5: DELL | B5: 65W | C5: 100-240V~1.6A/50-60Hz (bivolt) | D5: 19.5V ~ 3.34A | E5: LA65NS2-01 | F5: 06TM1C | G5: PA-12 FAMILY | H5: LITE-ON TECHNOLOGY CORPORATION | I5: 1 carregador completo | J5: BOM | K5: Sem avarias aparentes | L5: #VALUE!
A6: DELL | B6: 65W | C6: 100-240V~1.6A/50-60Hz (bivolt) | D6: 19.5V ~ 3.34A | E6: LA65NS2-01 | F6: 06TM1C | G6: PA-12 FAMILY | H6: LITE-ON TECHNOLOGY CORPORATION | I6: 1 carregador completo | J6: BOM | K6: Sem avarias aparentes | L6: #VALUE!
A7: DELL | B7: 65W | C7: 100-240V~1.6A/50-60Hz (bivolt) | D7: 19.5V ~ 3.34A | E7: LA65NS2-01 | F7: 06TM1C | G7: PA-12 FAMILY | H7: LITE-ON TECHNOLOGY CORPORATION | I7: 1 carregador completo | J7: BOM | K7: Sem avarias aparentes | L7: #VALUE!
A8: DELL | B8: 65W | C8: 100-240V~1.6A/50-60Hz (bivolt) | D8: 19.5V ~ 3.34A | E8: LA65NS2-01 | F8: 06TM1C | G8: PA-12 FAMILY | H8: LITE-ON TECHNOLOGY CORPORATION | I8: Sem cabo de força | J8: OK | K8: Bastante arranhado
A9: DELL | B9: 65W | C9: 100-240V~1.5A/50-60Hz (bivolt) | D9: 19.5V ~ 3.34A | E9: DA65PM111 | F9: MK947 | G9: CA Dell | H9: DELL Inc. | I9: 1 carregador completo | J9: BOM | K9: sem avarias aparentes | L9: #VALUE!
A10: DELL | B10: 65W | C10: Bivolt automatico (100-240V ~ 1.6A) | D10: 19.5V ~ 3.34A | E10: LA65NS2-01 | F10: 01N1FJ | G10: PA-12 FAMILY | H10: DELL Inc. | I10: 1 carregador COMPLETO | J10: BOM | K10: sem avarias aparentes
A11: DELL | B11: 65W | C11: Bivolt automatico (100-240V ~ 1.6A) | D11: 19.5V ~ 3.34A | E11: LA65NS2-01 | F11: 01N1FJ | G11: PA-12 FAMILY | H11: DELL Inc. | I11: 1 carregador COMPLETO | J11: BOM | K11: sem avarias aparentes | L11: #VALUE!
A12: Leader Electronics | C12: 100-240V ~ 50/60Hz 0.5A(Bivolt) | D12: 12V - 1.0A | E12: MU12-2120100-A1 | I12: 1 fonte de alimentação | J12: BOM | K12: sem avarias aparentes
A13: Leader Electronics | C13: 100-240V(Bivolt) | D13: 12V - 1.0A | E13: MU12-2120100-C5 | I13: 1 fonte de alimentação | J13: BOM | K13: sem avarias aparentes | L13: #VALUE!
A14: SWITCHING ADAPTOR | C14: 100-240V(Bivolt) | D14: DC 12V E 1000mA(1A) | I14: Adaptador de energia | J14: OK | K14: bastante sujo e com marcas de amarelamento
A15: Samsung | B15: 15W | C15: 100-240V ~ 50/60Hz 0.5A(Bivolt) | D15: 9,0V-1,67A | I15: Carregador COMPLETO cabo USB-C e adapatador sansung | J15: BOM | K15: sem avarias aparentes | L15: #VALUE!
A16: Samsung | B16: 15W | C16: 100-240V ~ 50/60Hz 0.5A(Bivolt) | D16: 9,0V-1,67A | I16: Carregador COMPLETO cabo USB-C e adapatador sansung | J16: BOM | K16: sem avarias aparentes | L16: #VALUE!
A17: Mass Power | C17: 100-240V~, 50/60Hz, 0.2A(Bivolt) | D17: 5.0V-0.6A | E17: NBS05B050060VB | I17: Adaptador de tomada | J17: BOM | K17: sem avarias aparentes
A18: Vasata | C18: 100-240V~50/60Hz 0.3A(Bivolt) | D18: 9.0V-0.6A (5.4W) | E18: P090060-2C1 | I18: Alimentação/Carregador | J18: BOM | K18: sem avarias aparentes
A19: FG | C19: 100-240V | D19: 12V em Corrente Contínua (DC) | E19: FC 12 02SI | I19: fonte de alimentação | J19: BOM | K19: sem avarias aparentes

Sheet A+
A1: MARCA | B1: MODELO | C1: Padrão Wi-Fi | D1: Velocidade Max | E1: Frequência | F1: Recursos extras | G1: Tec/REDE | H1: INTERFACE | I1: IMAGEM
A2: Genérico | B2: WiFi6-1300M (SKU: FY-01076) | C2: Wi-Fi 6 | D2: 1300Mbps | E2: Banda Dupla (2.4 GHz e 5.0 GHz) | F2: Conectividade Bluetooth(BT) integrada | G2: MU-MIMO | H2: Conexão USB
A3: Genérico | B3: WiFi6-1300M (SKU: FY-01076) | C3: Wi-Fi 6 | D3: 1300Mbps | E3: Banda Dupla (2.4 GHz e 5.0 GHz) | F3: Conectividade Bluetooth(BT) integrada | G3: MU-MIMO | H3: Conexão USB
A4: Genérico | B4: WiFi6-1300M (SKU: FY-01076) | C4: Wi-Fi 6 | D4: 1300Mbps | E4: Banda Dupla (2.4 GHz e 5.0 GHz) | F4: Conectividade Bluetooth(BT) integrada | G4: MU-MIMO | H4: Conexão USB
A5: Genérico | B5: WiFi6-1300M (SKU: FY-01076) | C5: Wi-Fi 6 | D5: 1300Mbps | E5: Banda Dupla (2.4 GHz e 5.0 GHz) | F5: Conectividade Bluetooth(BT) integrada | G5: MU-MIMO | H5: Conexão USB
A7: MARCA | B7: MODELO | C7: Padrão Wi-Fi | D7: Tipo de Dispositivo | E7: Interface/Rede | F7: Recursos/Segurança | G7: Suporte/VPN | H7: Alime/Elétrica | I7: Homologação | J7: OBS | K7: IMAGEM
A8: CISCO | B8: WRVS4400N V2 | C8: IEEE 802.11n | D8: Roteador de Segurança Gigabit Wireless-N com VPN | E8: 4 portas LAN Gigabit(10/100/1000 Mbps) 1 porta WAN Gigabit (10/100/1000 Mbps) | F8: Firewall SPI, Prevenção de Dos, Filtro de URL/Palavras-chave | G8: IPsec VPN (até 32 túneis simultaneos), QuickVPN | H8: 12V DC, 1A | I8: Certificado Anatel | J8: Alguns arranhões estado OK
A9: CISCO | B9: Cisco Aironet 1602I | C9: IEEE 802.11a, 802.11b, 802.11g e 802.11n | D9: Ponto de acesso corporativo indoor dual-band, com antenas internas | E9: 1 porta 10/100/1000BASE-T (RJ-45) + porta de console (RJ-45) | F9: WPA/WPA2, 802.1X, AES/TKIP; detecção de AP não autorizado e proteção de quadros de gerenciamento | G9: Sem VPN integrada; operação por controladora Cisco ou autônoma, conforme a versão | H9: 44–57 V DC; PoE IEEE 802.3af; consumo de 12,95 W | I9: Homologação Anatel não confirmada; verificar a etiqueta e o número do equipamento | J9: Amarelado e alguns arranhões estado Ok
A11: MARCA | B11: Modelo | C11: Área Ativa (Diagonal) | D11: Dimensões da Área Ativa | E11: Alimentação da Mesa | F11: Código de Barras (EAN)/FCC | G11: Alimentação da Caneta | H11: Níveis de Pressão da Caneta | I11: Resolução | J11: País de Fabricação | K11: IMAGEM
A12: C3 Tech (Distribuído por Coletek) | B12: Media Tablet 14.1" Prata (TB141) | C12: 14.1 Polegadas | D12: Aproximadamente 30,4 cm x 19,0 cm | E12: USB DC 5V - 40mA (Consumo elétrico ultra baixo) | F12: 7898927890254 | G12: 1 Pilha AAA (Palito) | H12: 1024 níveis de sensibilidade | I12: Até 4000 LPI (Linhas por polegada) | J12: w
A13: Wacom | B13: Intuos4 Large (PTK-840) | C13: 15,1 polegadas (383,5 mm) | D13: 325,1 x 203,2 mm | E13: 5V ⎓ 300mA (Via USB) | F13: HV4PTK | G13: Ressonância Eletromagnética (Sem fio e sem bateria) | H13: 2.048 níveis | I13: 5.080 lpi (Linhas por polegada) | J13: China
A15: COMPONENTE | B15: FORMATO | C15: TIPO | D15: QUANT | E15: MODELO | F15: OBSERVAÇÃO | G15: imagem
A16: RAM | B16: UDIMM/DIMM | C16: DDR | D16: 21
A17: RAM | B17: UDIMM/DIMM | C17: DDR | D17: 4
A18: PLACA DE VIDEO | C18: baixo perfil | D18: 6 | E18: ATI/AMD RADEON
A19: PLACA PCI | D19: 1 | E19: Pinnacle Systems
A20: Placa de Rede Sem Fio (Wi-Fi) | D20: 6 | E20: D-Link DWA-525 Wireless N 150 | F20: Circuito verde, etiqueta branca grande, grafismo laranja e preto com detalhes em triângulo.
A21: Placa Controladora / Interface | B21: PCI Padrão ou PCIe x1 | D21: 1 | E21: Genérica / Antiga | F21: Placa pequena escura (preta) com conectores externos no espelho (pode ser USB ou Som).
A22: Placa de Vídeo ou Rede de Servidor | B22: PCI / AGP ou PCIe | C22: PCI com porta paralela DB25 (ou serial/paralela), | D22: 1 | E22: Modelo com refrigeração passiva (Ex: GPU básica antiga ou placa de rede dedicada) | F22: Placa de circuito verde comprida com um grande dissipador de calor preto passivo.
A23: Placa de Expansão / Interface | D23: 2 | E23: Placa vertical estreita com circuito escuro/preto e conexão traseira (provável controladora). | F23: Genérica
A24: RAM | B24: Corsair | C24: DIMM | D24: 12 | E24: Corsair Value Select DDR3 | F24: Indicado para motherboards (placas-mãe) de PCs de escritório ou computadores desktop mais antigos compatíveis com tecnologia DDR3.
A25: RAM | C25: DIMM | D25: 10 | F25: Tecnologias mais antigas como SDRAM, DDR1 ou DDR2
A26: RAM | C26: DIMM | D26: 2 | F26: computadores de secretária (desktop)
A27: RAM | C27: dependendo do formato exato (DIMM/RDIMM) | D27: 2 | F27: DDR3
A28: RAM | C28: DIMM | D28: 6 | F28: Pentes de memória RAM UDIMM/DIMM de 240 pinos para PC de secretária
A29: RAM | C29: SO-DIMM | D29: 8 | F29: chips de memória soldados à placa de circuito impresso (PCB) verde, com contactos dourados na parte inferior e etiquetas autocolantes brancas com códigos de barras e especificações técnicas de fábrica.

Sheet Dados Gráfico
A1: Família | B1: Departamento normalizado | D1: Departamento | E1: Desktops/Micros | F1: Monitores | G1: Notebooks | H1: Impressoras | I1: Telefonia | J1: Outros
A2: =IF(TRIM(#REF!)="","Categoria não informada",IF(LEFT(UPPER(TRIM(#REF!)),7)="MONITOR","Monitores",IF(OR(LEFT(UPPER(TRIM(#REF!)),7)="DESKTOP",UPPER(TRIM(#REF!))="MICRO",LEFT(UPPER(TRIM(#REF!)),7)="MONTADO"),"Desktops/Micros",IF(LEFT(UPPER(TRIM(#REF!)),8)="NOTEBOOK","Notebooks",IF(LEFT(UPPER(TRIM(#REF!)),10)="IMPRESSORA","Impressoras",IF(LEFT(UPPER(TRIM(#REF!)),8)="TELEFONE","Telefonia","Outros")))))) -> #REF! | B2: =IF(TRIM(#REF!)="","SEM DEPARTAMENTO",IF(OR(UPPER(TRIM(#REF!))="TI",UPPER(TRIM(#REF!))="T.I"),"T.I",IF(OR(UPPER(TRIM(#REF!))="TECNICA",UPPER(TRIM(#REF!))="TÉCNICA"),"TÉCNICA",SUBSTITUTE(UPPER(TRIM(#REF!)),"SWICHER","SWITCHER")))) -> #REF! | D2: DEPÓSITO RH | E2: =COUNTIFS($B$2:$B$511,$D2,$A$2:$A$511,E$1) -> 0 | F2: =COUNTIFS($B$2:$B$511,$D2,$A$2:$A$511,F$1) -> 0 | G2: =COUNTIFS($B$2:$B$511,$D2,$A$2:$A$511,G$1) -> 0 | H2: =COUNTIFS($B$2:$B$511,$D2,$A$2:$A$511,H$1) -> 0 | I2: =COUNTIFS($B$2:$B$511,$D2,$A$2:$A$511,I$1) -> 0 | J2: =COUNTIFS($B$2:$B$511,$D2,$A$2:$A$511,J$1) -> 0
A3: =IF(TRIM(#REF!)="","Categoria não informada",IF(LEFT(UPPER(TRIM(#REF!)),7)="MONITOR","Monitores",IF(OR(LEFT(UPPER(TRIM(#REF!)),7)="DESKTOP",UPPER(TRIM(#REF!))="MICRO",LEFT(UPPER(TRIM(#REF!)),7)="MONTADO"),"Desktops/Micros",IF(LEFT(UPPER(TRIM(#REF!)),8)="NOTEBOOK","Notebooks",IF(LEFT(UPPER(TRIM(#REF!)),10)="IMPRESSORA","Impressoras",IF(LEFT(UPPER(TRIM(#REF!)),8)="TELEFONE","Telefonia","Outros")))))) -> #REF! | B3: =IF(TRIM(#REF!)="","SEM DEPARTAMENTO",IF(OR(UPPER(TRIM(#REF!))="TI",UPPER(TRIM(#REF!))="T.I"),"T.I",IF(OR(UPPER(TRIM(#REF!))="TECNICA",UPPER(TRIM(#REF!))="TÉCNICA"),"TÉCNICA",SUBSTITUTE(UPPER(TRIM(#REF!)),"SWICHER","SWITCHER")))) -> #REF! | D3: JORNALISMO | E3: =COUNTIFS($B$2:$B$511,$D3,$A$2:$A$511,E$1) -> 0 | F3: =COUNTIFS($B$2:$B$511,$D3,$A$2:$A$511,F$1) -> 0 | G3: =COUNTIFS($B$2:$B$511,$D3,$A$2:$A$511,G$1) -> 0 | H3: =COUNTIFS($B$2:$B$511,$D3,$A$2:$A$511,H$1) -> 0 | I3: =COUNTIFS($B$2:$B$511,$D3,$A$2:$A$511,I$1) -> 0 | J3: =COUNTIFS($B$2:$B$511,$D3,$A$2:$A$511,J$1) -> 0
A4: =IF(TRIM(#REF!)="","Categoria não informada",IF(LEFT(UPPER(TRIM(#REF!)),7)="MONITOR","Monitores",IF(OR(LEFT(UPPER(TRIM(#REF!)),7)="DESKTOP",UPPER(TRIM(#REF!))="MICRO",LEFT(UPPER(TRIM(#REF!)),7)="MONTADO"),"Desktops/Micros",IF(LEFT(UPPER(TRIM(#REF!)),8)="NOTEBOOK","Notebooks",IF(LEFT(UPPER(TRIM(#REF!)),10)="IMPRESSORA","Impressoras",IF(LEFT(UPPER(TRIM(#REF!)),8)="TELEFONE","Telefonia","Outros")))))) -> #REF! | B4: =IF(TRIM(#REF!)="","SEM DEPARTAMENTO",IF(OR(UPPER(TRIM(#REF!))="TI",UPPER(TRIM(#REF!))="T.I"),"T.I",IF(OR(UPPER(TRIM(#REF!))="TECNICA",UPPER(TRIM(#REF!))="TÉCNICA"),"TÉCNICA",SUBSTITUTE(UPPER(TRIM(#REF!)),"SWICHER","SWITCHER")))) -> #REF! | D4: MARKETING | E4: =COUNTIFS($B$2:$B$511,$D4,$A$2:$A$511,E$1) -> 0 | F4: =COUNTIFS($B$2:$B$511,$D4,$A$2:$A$511,F$1) -> 0 | G4: =COUNTIFS($B$2:$B$511,$D4,$A$2:$A$511,G$1) -> 0 | H4: =COUNTIFS($B$2:$B$511,$D4,$A$2:$A$511,H$1) -> 0 | I4: =COUNTIFS($B$2:$B$511,$D4,$A$2:$A$511,I$1) -> 0 | J4: =COUNTIFS($B$2:$B$511,$D4,$A$2:$A$511,J$1) -> 0
A5: =IF(TRIM(#REF!)="","Categoria não informada",IF(LEFT(UPPER(TRIM(#REF!)),7)="MONITOR","Monitores",IF(OR(LEFT(UPPER(TRIM(#REF!)),7)="DESKTOP",UPPER(TRIM(#REF!))="MICRO",LEFT(UPPER(TRIM(#REF!)),7)="MONTADO"),"Desktops/Micros",IF(LEFT(UPPER(TRIM(#REF!)),8)="NOTEBOOK","Notebooks",IF(LEFT(UPPER(TRIM(#REF!)),10)="IMPRESSORA","Impressoras",IF(LEFT(UPPER(TRIM(#REF!)),8)="TELEFONE","Telefonia","Outros")))))) -> #REF! | B5: =IF(TRIM(#REF!)="","SEM DEPARTAMENTO",IF(OR(UPPER(TRIM(#REF!))="TI",UPPER(TRIM(#REF!))="T.I"),"T.I",IF(OR(UPPER(TRIM(#REF!))="TECNICA",UPPER(TRIM(#REF!))="TÉCNICA"),"TÉCNICA",SUBSTITUTE(UPPER(TRIM(#REF!)),"SWICHER","SWITCHER")))) -> #REF! | D5: SWITCHER | E5: =COUNTIFS($B$2:$B$511,$D5,$A$2:$A$511,E$1) -> 0 | F5: =COUNTIFS($B$2:$B$511,$D5,$A$2:$A$511,F$1) -> 0 | G5: =COUNTIFS($B$2:$B$511,$D5,$A$2:$A$511,G$1) -> 0 | H5: =COUNTIFS($B$2:$B$511,$D5,$A$2:$A$511,H$1) -> 0 | I5: =COUNTIFS($B$2:$B$511,$D5,$A$2:$A$511,I$1) -> 0 | J5: =COUNTIFS($B$2:$B$511,$D5,$A$2:$A$511,J$1) -> 0
A6: =IF(TRIM(#REF!)="","Categoria não informada",IF(LEFT(UPPER(TRIM(#REF!)),7)="MONITOR","Monitores",IF(OR(LEFT(UPPER(TRIM(#REF!)),7)="DESKTOP",UPPER(TRIM(#REF!))="MICRO",LEFT(UPPER(TRIM(#REF!)),7)="MONTADO"),"Desktops/Micros",IF(LEFT(UPPER(TRIM(#REF!)),8)="NOTEBOOK","Notebooks",IF(LEFT(UPPER(TRIM(#REF!)),10)="IMPRESSORA","Impressoras",IF(LEFT(UPPER(TRIM(#REF!)),8)="TELEFONE","Telefonia","Outros")))))) -> #REF! | B6: =IF(TRIM(#REF!)="","SEM DEPARTAMENTO",IF(OR(UPPER(TRIM(#REF!))="TI",UPPER(TRIM(#REF!))="T.I"),"T.I",IF(OR(UPPER(TRIM(#REF!))="TECNICA",UPPER(TRIM(#REF!))="TÉCNICA"),"TÉCNICA",SUBSTITUTE(UPPER(TRIM(#REF!)),"SWICHER","SWITCHER")))) -> #REF! | D6: COMERCIAL | E6: =COUNTIFS($B$2:$B$511,$D6,$A$2:$A$511,E$1) -> 0 | F6: =COUNTIFS($B$2:$B$511,$D6,$A$2:$A$511,F$1) -> 0 | G6: =COUNTIFS($B$2:$B$511,$D6,$A$2:$A$511,G$1) -> 0 | H6: =COUNTIFS($B$2:$B$511,$D6,$A$2:$A$511,H$1) -> 0 | I6: =COUNTIFS($B$2:$B$511,$D6,$A$2:$A$511,I$1) -> 0 | J6: =COUNTIFS($B$2:$B$511,$D6,$A$2:$A$511,J$1) -> 0
A7: =IF(TRIM(#REF!)="","Categoria não informada",IF(LEFT(UPPER(TRIM(#REF!)),7)="MONITOR","Monitores",IF(OR(LEFT(UPPER(TRIM(#REF!)),7)="DESKTOP",UPPER(TRIM(#REF!))="MICRO",LEFT(UPPER(TRIM(#REF!)),7)="MONTADO"),"Desktops/Micros",IF(LEFT(UPPER(TRIM(#REF!)),8)="NOTEBOOK","Notebooks",IF(LEFT(UPPER(TRIM(#REF!)),10)="IMPRESSORA","Impressoras",IF(LEFT(UPPER(TRIM(#REF!)),8)="TELEFONE","Telefonia","Outros")))))) -> #REF! | B7: =IF(TRIM(#REF!)="","SEM DEPARTAMENTO",IF(OR(UPPER(TRIM(#REF!))="TI",UPPER(TRIM(#REF!))="T.I"),"T.I",IF(OR(UPPER(TRIM(#REF!))="TECNICA",UPPER(TRIM(#REF!))="TÉCNICA"),"TÉCNICA",SUBSTITUTE(UPPER(TRIM(#REF!)),"SWICHER","SWITCHER")))) -> #REF! | D7: TÉCNICA | E7: =COUNTIFS($B$2:$B$511,$D7,$A$2:$A$511,E$1) -> 0 | F7: =COUNTIFS($B$2:$B$511,$D7,$A$2:$A$511,F$1) -> 0 | G7: =COUNTIFS($B$2:$B$511,$D7,$A$2:$A$511,G$1) -> 0 | H7: =COUNTIFS($B$2:$B$511,$D7,$A$2:$A$511,H$1) -> 0 | I7: =COUNTIFS($B$2:$B$511,$D7,$A$2:$A$511,I$1) -> 0 | J7: =COUNTIFS($B$2:$B$511,$D7,$A$2:$A$511,J$1) -> 0
A8: =IF(TRIM(#REF!)="","Categoria não informada",IF(LEFT(UPPER(TRIM(#REF!)),7)="MONITOR","Monitores",IF(OR(LEFT(UPPER(TRIM(#REF!)),7)="DESKTOP",UPPER(TRIM(#REF!))="MICRO",LEFT(UPPER(TRIM(#REF!)),7)="MONTADO"),"Desktops/Micros",IF(LEFT(UPPER(TRIM(#REF!)),8)="NOTEBOOK","Notebooks",IF(LEFT(UPPER(TRIM(#REF!)),10)="IMPRESSORA","Impressoras",IF(LEFT(UPPER(TRIM(#REF!)),8)="TELEFONE","Telefonia","Outros")))))) -> #REF! | B8: =IF(TRIM(#REF!)="","SEM DEPARTAMENTO",IF(OR(UPPER(TRIM(#REF!))="TI",UPPER(TRIM(#REF!))="T.I"),"T.I",IF(OR(UPPER(TRIM(#REF!))="TECNICA",UPPER(TRIM(#REF!))="TÉCNICA"),"TÉCNICA",SUBSTITUTE(UPPER(TRIM(#REF!)),"SWICHER","SWITCHER")))) -> #REF! | D8: ADMINISTRATIVO | E8: =COUNTIFS($B$2:$B$511,$D8,$A$2:$A$511,E$1) -> 0 | F8: =COUNTIFS($B$2:$B$511,$D8,$A$2:$A$511,F$1) -> 0 | G8: =COUNTIFS($B$2:$B$511,$D8,$A$2:$A$511,G$1) -> 0 | H8: =COUNTIFS($B$2:$B$511,$D8,$A$2:$A$511,H$1) -> 0 | I8: =COUNTIFS($B$2:$B$511,$D8,$A$2:$A$511,I$1) -> 0 | J8: =COUNTIFS($B$2:$B$511,$D8,$A$2:$A$511,J$1) -> 0
A9: =IF(TRIM(#REF!)="","Categoria não informada",IF(LEFT(UPPER(TRIM(#REF!)),7)="MONITOR","Monitores",IF(OR(LEFT(UPPER(TRIM(#REF!)),7)="DESKTOP",UPPER(TRIM(#REF!))="MICRO",LEFT(UPPER(TRIM(#REF!)),7)="MONTADO"),"Desktops/Micros",IF(LEFT(UPPER(TRIM(#REF!)),8)="NOTEBOOK","Notebooks",IF(LEFT(UPPER(TRIM(#REF!)),10)="IMPRESSORA","Impressoras",IF(LEFT(UPPER(TRIM(#REF!)),8)="TELEFONE","Telefonia","Outros")))))) -> #REF! | B9: =IF(TRIM(#REF!)="","SEM DEPARTAMENTO",IF(OR(UPPER(TRIM(#REF!))="TI",UPPER(TRIM(#REF!))="T.I"),"T.I",IF(OR(UPPER(TRIM(#REF!))="TECNICA",UPPER(TRIM(#REF!))="TÉCNICA"),"TÉCNICA",SUBSTITUTE(UPPER(TRIM(#REF!)),"SWICHER","SWITCHER")))) -> #REF! | D9: RH | E9: =COUNTIFS($B$2:$B$511,$D9,$A$2:$A$511,E$1) -> 0 | F9: =COUNTIFS($B$2:$B$511,$D9,$A$2:$A$511,F$1) -> 0 | G9: =COUNTIFS($B$2:$B$511,$D9,$A$2:$A$511,G$1) -> 0 | H9: =COUNTIFS($B$2:$B$511,$D9,$A$2:$A$511,H$1) -> 0 | I9: =COUNTIFS($B$2:$B$511,$D9,$A$2:$A$511,I$1) -> 0 | J9: =COUNTIFS($B$2:$B$511,$D9,$A$2:$A$511,J$1) -> 0
A10: =IF(TRIM(#REF!)="","Categoria não informada",IF(LEFT(UPPER(TRIM(#REF!)),7)="MONITOR","Monitores",IF(OR(LEFT(UPPER(TRIM(#REF!)),7)="DESKTOP",UPPER(TRIM(#REF!))="MICRO",LEFT(UPPER(TRIM(#REF!)),7)="MONTADO"),"Desktops/Micros",IF(LEFT(UPPER(TRIM(#REF!)),8)="NOTEBOOK","Notebooks",IF(LEFT(UPPER(TRIM(#REF!)),10)="IMPRESSORA","Impressoras",IF(LEFT(UPPER(TRIM(#REF!)),8)="TELEFONE","Telefonia","Outros")))))) -> #REF! | B10: =IF(TRIM(#REF!)="","SEM DEPARTAMENTO",IF(OR(UPPER(TRIM(#REF!))="TI",UPPER(TRIM(#REF!))="T.I"),"T.I",IF(OR(UPPER(TRIM(#REF!))="TECNICA",UPPER(TRIM(#REF!))="TÉCNICA"),"TÉCNICA",SUBSTITUTE(UPPER(TRIM(#REF!)),"SWICHER","SWITCHER")))) -> #REF! | D10: T.I | E10: =COUNTIFS($B$2:$B$511,$D10,$A$2:$A$511,E$1) -> 0 | F10: =COUNTIFS($B$2:$B$511,$D10,$A$2:$A$511,F$1) -> 0 | G10: =COUNTIFS($B$2:$B$511,$D10,$A$2:$A$511,G$1) -> 0 | H10: =COUNTIFS($B$2:$B$511,$D10,$A$2:$A$511,H$1) -> 0 | I10: =COUNTIFS($B$2:$B$511,$D10,$A$2:$A$511,I$1) -> 0 | J10: =COUNTIFS($B$2:$B$511,$D10,$A$2:$A$511,J$1) -> 0
A11: =IF(TRIM(#REF!)="","Categoria não informada",IF(LEFT(UPPER(TRIM(#REF!)),7)="MONITOR","Monitores",IF(OR(LEFT(UPPER(TRIM(#REF!)),7)="DESKTOP",UPPER(TRIM(#REF!))="MICRO",LEFT(UPPER(TRIM(#REF!)),7)="MONTADO"),"Desktops/Micros",IF(LEFT(UPPER(TRIM(#REF!)),8)="NOTEBOOK","Notebooks",IF(LEFT(UPPER(TRIM(#REF!)),10)="IMPRESSORA","Impressoras",IF(LEFT(UPPER(TRIM(#REF!)),8)="TELEFONE","Telefonia","Outros")))))) -> #REF! | B11: =IF(TRIM(#REF!)="","SEM DEPARTAMENTO",IF(OR(UPPER(TRIM(#REF!))="TI",UPPER(TRIM(#REF!))="T.I"),"T.I",IF(OR(UPPER(TRIM(#REF!))="TECNICA",UPPER(TRIM(#REF!))="TÉCNICA"),"TÉCNICA",SUBSTITUTE(UPPER(TRIM(#REF!)),"SWICHER","SWITCHER")))) -> #REF! | D11: FINANCEIRO | E11: =COUNTIFS($B$2:$B$511,$D11,$A$2:$A$511,E$1) -> 0 | F11: =COUNTIFS($B$2:$B$511,$D11,$A$2:$A$511,F$1) -> 0 | G11: =COUNTIFS($B$2:$B$511,$D11,$A$2:$A$511,G$1) -> 0 | H11: =COUNTIFS($B$2:$B$511,$D11,$A$2:$A$511,H$1) -> 0 | I11: =COUNTIFS($B$2:$B$511,$D11,$A$2:$A$511,I$1) -> 0 | J11: =COUNTIFS($B$2:$B$511,$D11,$A$2:$A$511,J$1) -> 0
A12: =IF(TRIM(#REF!)="","Categoria não informada",IF(LEFT(UPPER(TRIM(#REF!)),7)="MONITOR","Monitores",IF(OR(LEFT(UPPER(TRIM(#REF!)),7)="DESKTOP",UPPER(TRIM(#REF!))="MICRO",LEFT(UPPER(TRIM(#REF!)),7)="MONTADO"),"Desktops/Micros",IF(LEFT(UPPER(TRIM(#REF!)),8)="NOTEBOOK","Notebooks",IF(LEFT(UPPER(TRIM(#REF!)),10)="IMPRESSORA","Impressoras",IF(LEFT(UPPER(TRIM(#REF!)),8)="TELEFONE","Telefonia","Outros")))))) -> #REF! | B12: =IF(TRIM(#REF!)="","SEM DEPARTAMENTO",IF(OR(UPPER(TRIM(#REF!))="TI",UPPER(TRIM(#REF!))="T.I"),"T.I",IF(OR(UPPER(TRIM(#REF!))="TECNICA",UPPER(TRIM(#REF!))="TÉCNICA"),"TÉCNICA",SUBSTITUTE(UPPER(TRIM(#REF!)),"SWICHER","SWITCHER")))) -> #REF! | D12: OPEC | E12: =COUNTIFS($B$2:$B$511,$D12,$A$2:$A$511,E$1) -> 0 | F12: =COUNTIFS($B$2:$B$511,$D12,$A$2:$A$511,F$1) -> 0 | G12: =COUNTIFS($B$2:$B$511,$D12,$A$2:$A$511,G$1) -> 0 | H12: =COUNTIFS($B$2:$B$511,$D12,$A$2:$A$511,H$1) -> 0 | I12: =COUNTIFS($B$2:$B$511,$D12,$A$2:$A$511,I$1) -> 0 | J12: =COUNTIFS($B$2:$B$511,$D12,$A$2:$A$511,J$1) -> 0
A13: =IF(TRIM(#REF!)="","Categoria não informada",IF(LEFT(UPPER(TRIM(#REF!)),7)="MONITOR","Monitores",IF(OR(LEFT(UPPER(TRIM(#REF!)),7)="DESKTOP",UPPER(TRIM(#REF!))="MICRO",LEFT(UPPER(TRIM(#REF!)),7)="MONTADO"),"Desktops/Micros",IF(LEFT(UPPER(TRIM(#REF!)),8)="NOTEBOOK","Notebooks",IF(LEFT(UPPER(TRIM(#REF!)),10)="IMPRESSORA","Impressoras",IF(LEFT(UPPER(TRIM(#REF!)),8)="TELEFONE","Telefonia","Outros")))))) -> #REF! | B13: =IF(TRIM(#REF!)="","SEM DEPARTAMENTO",IF(OR(UPPER(TRIM(#REF!))="TI",UPPER(TRIM(#REF!))="T.I"),"T.I",IF(OR(UPPER(TRIM(#REF!))="TECNICA",UPPER(TRIM(#REF!))="TÉCNICA"),"TÉCNICA",SUBSTITUTE(UPPER(TRIM(#REF!)),"SWICHER","SWITCHER")))) -> #REF! | D13: CONTABILIDADE | E13: =COUNTIFS($B$2:$B$511,$D13,$A$2:$A$511,E$1) -> 0 | F13: =COUNTIFS($B$2:$B$511,$D13,$A$2:$A$511,F$1) -> 0 | G13: =COUNTIFS($B$2:$B$511,$D13,$A$2:$A$511,G$1) -> 0 | H13: =COUNTIFS($B$2:$B$511,$D13,$A$2:$A$511,H$1) -> 0 | I13: =COUNTIFS($B$2:$B$511,$D13,$A$2:$A$511,I$1) -> 0 | J13: =COUNTIFS($B$2:$B$511,$D13,$A$2:$A$511,J$1) -> 0
A14: =IF(TRIM(#REF!)="","Categoria não informada",IF(LEFT(UPPER(TRIM(#REF!)),7)="MONITOR","Monitores",IF(OR(LEFT(UPPER(TRIM(#REF!)),7)="DESKTOP",UPPER(TRIM(#REF!))="MICRO",LEFT(UPPER(TRIM(#REF!)),7)="MONTADO"),"Desktops/Micros",IF(LEFT(UPPER(TRIM(#REF!)),8)="NOTEBOOK","Notebooks",IF(LEFT(UPPER(TRIM(#REF!)),10)="IMPRESSORA","Impressoras",IF(LEFT(UPPER(TRIM(#REF!)),8)="TELEFONE","Telefonia","Outros")))))) -> #REF! | B14: =IF(TRIM(#REF!)="","SEM DEPARTAMENTO",IF(OR(UPPER(TRIM(#REF!))="TI",UPPER(TRIM(#REF!))="T.I"),"T.I",IF(OR(UPPER(TRIM(#REF!))="TECNICA",UPPER(TRIM(#REF!))="TÉCNICA"),"TÉCNICA",SUBSTITUTE(UPPER(TRIM(#REF!)),"SWICHER","SWITCHER")))) -> #REF! | D14: DEMAIS DEPARTAMENTOS | E14: =COUNTIF($A$2:$A$511,E$1)-SUM(E2:E13)-E15 -> 0 | F14: =COUNTIF($A$2:$A$511,F$1)-SUM(F2:F13)-F15 -> 0 | G14: =COUNTIF($A$2:$A$511,G$1)-SUM(G2:G13)-G15 -> 0 | H14: =COUNTIF($A$2:$A$511,H$1)-SUM(H2:H13)-H15 -> 0 | I14: =COUNTIF($A$2:$A$511,I$1)-SUM(I2:I13)-I15 -> 0 | J14: =COUNTIF($A$2:$A$511,J$1)-SUM(J2:J13)-J15 -> 0
A15: =IF(TRIM(#REF!)="","Categoria não informada",IF(LEFT(UPPER(TRIM(#REF!)),7)="MONITOR","Monitores",IF(OR(LEFT(UPPER(TRIM(#REF!)),7)="DESKTOP",UPPER(TRIM(#REF!))="MICRO",LEFT(UPPER(TRIM(#REF!)),7)="MONTADO"),"Desktops/Micros",IF(LEFT(UPPER(TRIM(#REF!)),8)="NOTEBOOK","Notebooks",IF(LEFT(UPPER(TRIM(#REF!)),10)="IMPRESSORA","Impressoras",IF(LEFT(UPPER(TRIM(#REF!)),8)="TELEFONE","Telefonia","Outros")))))) -> #REF! | B15: =IF(TRIM(#REF!)="","SEM DEPARTAMENTO",IF(OR(UPPER(TRIM(#REF!))="TI",UPPER(TRIM(#REF!))="T.I"),"T.I",IF(OR(UPPER(TRIM(#REF!))="TECNICA",UPPER(TRIM(#REF!))="TÉCNICA"),"TÉCNICA",SUBSTITUTE(UPPER(TRIM(#REF!)),"SWICHER","SWITCHER")))) -> #REF! | D15: SEM DEPARTAMENTO | E15: =COUNTIFS($B$2:$B$511,"SEM DEPARTAMENTO",$A$2:$A$511,E$1) -> 0 | F15: =COUNTIFS($B$2:$B$511,"SEM DEPARTAMENTO",$A$2:$A$511,F$1) -> 0 | G15: =COUNTIFS($B$2:$B$511,"SEM DEPARTAMENTO",$A$2:$A$511,G$1) -> 0 | H15: =COUNTIFS($B$2:$B$511,"SEM DEPARTAMENTO",$A$2:$A$511,H$1) -> 0 | I15: =COUNTIFS($B$2:$B$511,"SEM DEPARTAMENTO",$A$2:$A$511,I$1) -> 0 | J15: =COUNTIFS($B$2:$B$511,"SEM DEPARTAMENTO",$A$2:$A$511,J$1) -> 0
A16: =IF(TRIM(#REF!)="","Categoria não informada",IF(LEFT(UPPER(TRIM(#REF!)),7)="MONITOR","Monitores",IF(OR(LEFT(UPPER(TRIM(#REF!)),7)="DESKTOP",UPPER(TRIM(#REF!))="MICRO",LEFT(UPPER(TRIM(#REF!)),7)="MONTADO"),"Desktops/Micros",IF(LEFT(UPPER(TRIM(#REF!)),8)="NOTEBOOK","Notebooks",IF(LEFT(UPPER(TRIM(#REF!)),10)="IMPRESSORA","Impressoras",IF(LEFT(UPPER(TRIM(#REF!)),8)="TELEFONE","Telefonia","Outros")))))) -> #REF! | B16: =IF(TRIM(#REF!)="","SEM DEPARTAMENTO",IF(OR(UPPER(TRIM(#REF!))="TI",UPPER(TRIM(#REF!))="T.I"),"T.I",IF(OR(UPPER(TRIM(#REF!))="TECNICA",UPPER(TRIM(#REF!))="TÉCNICA"),"TÉCNICA",SUBSTITUTE(UPPER(TRIM(#REF!)),"SWICHER","SWITCHER")))) -> #REF!
A17: =IF(TRIM(#REF!)="","Categoria não informada",IF(LEFT(UPPER(TRIM(#REF!)),7)="MONITOR","Monitores",IF(OR(LEFT(UPPER(TRIM(#REF!)),7)="DESKTOP",UPPER(TRIM(#REF!))="MICRO",LEFT(UPPER(TRIM(#REF!)),7)="MONTADO"),"Desktops/Micros",IF(LEFT(UPPER(TRIM(#REF!)),8)="NOTEBOOK","Notebooks",IF(LEFT(UPPER(TRIM(#REF!)),10)="IMPRESSORA","Impressoras",IF(LEFT(UPPER(TRIM(#REF!)),8)="TELEFONE","Telefonia","Outros")))))) -> #REF! | B17: =IF(TRIM(#REF!)="","SEM DEPARTAMENTO",IF(OR(UPPER(TRIM(#REF!))="TI",UPPER(TRIM(#REF!))="T.I"),"T.I",IF(OR(UPPER(TRIM(#REF!))="TECNICA",UPPER(TRIM(#REF!))="TÉCNICA"),"TÉCNICA",SUBSTITUTE(UPPER(TRIM(#REF!)),"SWICHER","SWITCHER")))) -> #REF!
A18: =IF(TRIM(#REF!)="","Categoria não informada",IF(LEFT(UPPER(TRIM(#REF!)),7)="MONITOR","Monitores",IF(OR(LEFT(UPPER(TRIM(#REF!)),7)="DESKTOP",UPPER(TRIM(#REF!))="MICRO",LEFT(UPPER(TRIM(#REF!)),7)="MONTADO"),"Desktops/Micros",IF(LEFT(UPPER(TRIM(#REF!)),8)="NOTEBOOK","Notebooks",IF(LEFT(UPPER(TRIM(#REF!)),10)="IMPRESSORA","Impressoras",IF(LEFT(UPPER(TRIM(#REF!)),8)="TELEFONE","Telefonia","Outros")))))) -> #REF! | B18: =IF(TRIM(#REF!)="","SEM DEPARTAMENTO",IF(OR(UPPER(TRIM(#REF!))="TI",UPPER(TRIM(#REF!))="T.I"),"T.I",IF(OR(UPPER(TRIM(#REF!))="TECNICA",UPPER(TRIM(#REF!))="TÉCNICA"),"TÉCNICA",SUBSTITUTE(UPPER(TRIM(#REF!)),"SWICHER","SWITCHER")))) -> #REF!
A19: =IF(TRIM(#REF!)="","Categoria não informada",IF(LEFT(UPPER(TRIM(#REF!)),7)="MONITOR","Monitores",IF(OR(LEFT(UPPER(TRIM(#REF!)),7)="DESKTOP",UPPER(TRIM(#REF!))="MICRO",LEFT(UPPER(TRIM(#REF!)),7)="MONTADO"),"Desktops/Micros",IF(LEFT(UPPER(TRIM(#REF!)),8)="NOTEBOOK","Notebooks",IF(LEFT(UPPER(TRIM(#REF!)),10)="IMPRESSORA","Impressoras",IF(LEFT(UPPER(TRIM(#REF!)),8)="TELEFONE","Telefonia","Outros")))))) -> #REF! | B19: =IF(TRIM(#REF!)="","SEM DEPARTAMENTO",IF(OR(UPPER(TRIM(#REF!))="TI",UPPER(TRIM(#REF!))="T.I"),"T.I",IF(OR(UPPER(TRIM(#REF!))="TECNICA",UPPER(TRIM(#REF!))="TÉCNICA"),"TÉCNICA",SUBSTITUTE(UPPER(TRIM(#REF!)),"SWICHER","SWITCHER")))) -> #REF!
A20: =IF(TRIM(#REF!)="","Categoria não informada",IF(LEFT(UPPER(TRIM(#REF!)),7)="MONITOR","Monitores",IF(OR(LEFT(UPPER(TRIM(#REF!)),7)="DESKTOP",UPPER(TRIM(#REF!))="MICRO",LEFT(UPPER(TRIM(#REF!)),7)="MONTADO"),"Desktops/Micros",IF(LEFT(UPPER(TRIM(#REF!)),8)="NOTEBOOK","Notebooks",IF(LEFT(UPPER(TRIM(#REF!)),10)="IMPRESSORA","Impressoras",IF(LEFT(UPPER(TRIM(#REF!)),8)="TELEFONE","Telefonia","Outros")))))) -> #REF! | B20: =IF(TRIM(#REF!)="","SEM DEPARTAMENTO",IF(OR(UPPER(TRIM(#REF!))="TI",UPPER(TRIM(#REF!))="T.I"),"T.I",IF(OR(UPPER(TRIM(#REF!))="TECNICA",UPPER(TRIM(#REF!))="TÉCNICA"),"TÉCNICA",SUBSTITUTE(UPPER(TRIM(#REF!)),"SWICHER","SWITCHER")))) -> #REF!
A21: =IF(TRIM(#REF!)="","Categoria não informada",IF(LEFT(UPPER(TRIM(#REF!)),7)="MONITOR","Monitores",IF(OR(LEFT(UPPER(TRIM(#REF!)),7)="DESKTOP",UPPER(TRIM(#REF!))="MICRO",LEFT(UPPER(TRIM(#REF!)),7)="MONTADO"),"Desktops/Micros",IF(LEFT(UPPER(TRIM(#REF!)),8)="NOTEBOOK","Notebooks",IF(LEFT(UPPER(TRIM(#REF!)),10)="IMPRESSORA","Impressoras",IF(LEFT(UPPER(TRIM(#REF!)),8)="TELEFONE","Telefonia","Outros")))))) -> #REF! | B21: =IF(TRIM(#REF!)="","SEM DEPARTAMENTO",IF(OR(UPPER(TRIM(#REF!))="TI",UPPER(TRIM(#REF!))="T.I"),"T.I",IF(OR(UPPER(TRIM(#REF!))="TECNICA",UPPER(TRIM(#REF!))="TÉCNICA"),"TÉCNICA",SUBSTITUTE(UPPER(TRIM(#REF!)),"SWICHER","SWITCHER")))) -> #REF!
A22: =IF(TRIM(#REF!)="","Categoria não informada",IF(LEFT(UPPER(TRIM(#REF!)),7)="MONITOR","Monitores",IF(OR(LEFT(UPPER(TRIM(#REF!)),7)="DESKTOP",UPPER(TRIM(#REF!))="MICRO",LEFT(UPPER(TRIM(#REF!)),7)="MONTADO"),"Desktops/Micros",IF(LEFT(UPPER(TRIM(#REF!)),8)="NOTEBOOK","Notebooks",IF(LEFT(UPPER(TRIM(#REF!)),10)="IMPRESSORA","Impressoras",IF(LEFT(UPPER(TRIM(#REF!)),8)="TELEFONE","Telefonia","Outros")))))) -> #REF! | B22: =IF(TRIM(#REF!)="","SEM DEPARTAMENTO",IF(OR(UPPER(TRIM(#REF!))="TI",UPPER(TRIM(#REF!))="T.I"),"T.I",IF(OR(UPPER(TRIM(#REF!))="TECNICA",UPPER(TRIM(#REF!))="TÉCNICA"),"TÉCNICA",SUBSTITUTE(UPPER(TRIM(#REF!)),"SWICHER","SWITCHER")))) -> #REF!
A23: =IF(TRIM(#REF!)="","Categoria não informada",IF(LEFT(UPPER(TRIM(#REF!)),7)="MONITOR","Monitores",IF(OR(LEFT(UPPER(TRIM(#REF!)),7)="DESKTOP",UPPER(TRIM(#REF!))="MICRO",LEFT(UPPER(TRIM(#REF!)),7)="MONTADO"),"Desktops/Micros",IF(LEFT(UPPER(TRIM(#REF!)),8)="NOTEBOOK","Notebooks",IF(LEFT(UPPER(TRIM(#REF!)),10)="IMPRESSORA","Impressoras",IF(LEFT(UPPER(TRIM(#REF!)),8)="TELEFONE","Telefonia","Outros")))))) -> #REF! | B23: =IF(TRIM(#REF!)="","SEM DEPARTAMENTO",IF(OR(UPPER(TRIM(#REF!))="TI",UPPER(TRIM(#REF!))="T.I"),"T.I",IF(OR(UPPER(TRIM(#REF!))="TECNICA",UPPER(TRIM(#REF!))="TÉCNICA"),"TÉCNICA",SUBSTITUTE(UPPER(TRIM(#REF!)),"SWICHER","SWITCHER")))) -> #REF!
A24: =IF(TRIM(#REF!)="","Categoria não informada",IF(LEFT(UPPER(TRIM(#REF!)),7)="MONITOR","Monitores",IF(OR(LEFT(UPPER(TRIM(#REF!)),7)="DESKTOP",UPPER(TRIM(#REF!))="MICRO",LEFT(UPPER(TRIM(#REF!)),7)="MONTADO"),"Desktops/Micros",IF(LEFT(UPPER(TRIM(#REF!)),8)="NOTEBOOK","Notebooks",IF(LEFT(UPPER(TRIM(#REF!)),10)="IMPRESSORA","Impressoras",IF(LEFT(UPPER(TRIM(#REF!)),8)="TELEFONE","Telefonia","Outros")))))) -> #REF! | B24: =IF(TRIM(#REF!)="","SEM DEPARTAMENTO",IF(OR(UPPER(TRIM(#REF!))="TI",UPPER(TRIM(#REF!))="T.I"),"T.I",IF(OR(UPPER(TRIM(#REF!))="TECNICA",UPPER(TRIM(#REF!))="TÉCNICA"),"TÉCNICA",SUBSTITUTE(UPPER(TRIM(#REF!)),"SWICHER","SWITCHER")))) -> #REF!
